Workbook
Name Status: 'Reference'!$A$4:$A$12
Name Formats: 'Reference'!$C$4:$C$7
Name Categories: 'Reference'!$E$4:$E$10
Name MeatType: 'Reference'!$G$4:$G$15
Name ChocolateType: 'Reference'!$I$4:$I$7
Name ChocolateSupplement: 'Reference'!$K$4:$K$6
Name LabelModes: 'Reference'!$T$4:$T$9
Name CompositeQuantityType: 'Reference'!$AE$4:$AE$5
Name TimePeriod: 'Reference'!$AK$4:$AK$8
Name Allergens: 'Reference'!$Y$4:$Y$17
Name Suppliers: 'Reference'!$O$4:$O$173
Name Countries: 'Reference'!$M$4:$M$244
Name Additive: 'Reference'!$AA$4:$AA$333
Name Function: 'Reference'!$AC$4:$AC$33
Name AfterOpenTimePeriod: 'Reference'!$AM$4:$AM$9

Sheet Ingredients
A1: Code | B1: Description | C1: New Code | D1: Parent Code | E1: Parent Description | F1: Parent Out of Date | G1: Update With Parent Nutritionals | H1: Scale Costs | I1: Source Of Data | J1: Ext. Code | K1: Data Set | L1: Status | M1: Format | N1: Additive | O1: Function | P1: Default Label Name | Q1: Default Label Mode | R1: QUID by Default | S1: Comments | T1: Total Shelf Life | U1: Total Shelf Life Period | V1: Total Shelf Life Comment | W1: Min. Shelf Life On Arrival | X1: Min. Shelf Life On Arrival Period | Y1: Min. Shelf Life On Arrival Comment | Z1: Shelf Life After Opening | AA1: Shelf Life After Opening Period | AB1: Shelf Life After Opening Comment | AC1: LeadTime | AD1: LeadTimePeriod | AE1: Min. Order Quantity | AF1: Hydration | AG1: Default Transfer Yield % | AH1: Cost | AI1: Supply Unit | AJ1: Category | AK1: Nutritional Weight | AL1: Energy (kJ) | AM1: Energy (kcal) | AN1: Protein | AO1: Fat | AP1: Fat - Saturates | AQ1: Fat - Monounsaturates | AR1: Fat - Polyunsaturates | AS1: Fat - Trans | AT1: Carbohydrate | AU1: Starch | AV1: Sugars | AW1: Polyols | AX1: Added Sugars | AY1: Fibre | AZ1: Sodium | BA1: Salt | BB1: Moisture | BC1: Nitrogen | BD1: Alcohol | BE1: Cholesterol | BF1: Ash | BG1: Caffeine | BH1: Potassium | BI1: Calcium | BJ1: Magnesium | BK1: Phosphorus | BL1: Iron | BM1: Copper | BN1: Zinc | BO1: Chloride | BP1: Manganese | BQ1: Selenium | BR1: Iodide | BS1: Retinol | BT1: Carotene | BU1: Vitamin A | BV1: Vitamin A (µg) | BW1: Vitamin C | BX1: Vitamin D (µg) | BY1: Vitamin D (IU) | BZ1: Vitamin E | CA1: Vitamin E (IU) | CB1: Thiamin | CC1: Riboflavin | CD1: Niacin | CE1: Tryptophan 60 | CF1: Tryptophan 60 (g) | CG1: Vitamin B6 | CH1: Vitamin B12 | CI1: Folate | CJ1: Pantothenate | CK1: Biotin | CL1: Cut Name | CM1: Is VL | CN1: Meat Fat | CO1: Meat Protein | CP1: Meat Collagen | CQ1: Meat Type | CR1: Raw Meat Equivalent | CS1: QUID as FSA | CT1: Chocolate Type | CU1: Chocolate Supplement | CV1: Cocoa Solids | CW1: Cocoa Butter | CX1: Milk Solids | CY1: Milk Fat | CZ1: Contains Vegetable Fat In Addition To Cocoa Butter | DA1: Supplier Comments | DB1: Countries of Origin | DC1: Countries of Manufacture | DD1: Tags
A2: NPD-I10748 | B2: Ground Cinnamon (AF, 500g) | D2: 13-874 | E2: Cinnamon, ground | F2: No | G2: No | H2: Yes | I2: Supplier specification | J2: P0018577 | K2: The Newt in Somerset | L2: Approved | M2: Ambient | N2: None | O2: None | P2: Cinnamon | Q2: Breakdown | R2: No | S2: Literature sources | T2: 18 | U2: Months | W2: 9 | X2: Months | AD2: Days | AE2: 0 | AF2: 0 | AG2: 100 | AH2: 5.75 | AI2: Tub | AJ2: Dry Goods | AK2: 100 | AL2: 1035 | AM2: 247 | AN2: 3.99 | AO2: 1.24 | AP2: 0 | AT2: 80.59 | AV2: 2 | AY2: 53.1 | AZ2: 10.00 | BA2: 0.025 | BC2: 0.64 | BD2: 0.0 | BH2: 431 | BI2: 1002 | BJ2: 60 | BK2: 64 | BL2: 8.32 | BM2: 0.34 | BN2: 1.8 | BO2: N | BP2: 17.47 | BQ2: 3 | BR2: N | BS2: 0 | BT2: 177 | BW2: 4 | BX2: 0.0 | BZ2: N | CA2: N | CB2: 0.02 | CC2: 0.04 | CD2: 1.3 | CE2: N | CG2: 0.16 | CH2: 0.0 | CI2: 6 | CJ2: 0.36 | CK2: N | CM2: No | DB2: Indonesia | DC2: United Kingdom
A3: NPD-I10752 | B3: Fresh Yeast, Mauri | D3: 17-378 | E3: Yeast, bakers, compressed | F3: No | G3: No | H3: Yes | I3: Nutritional from supplier specification. | J3: P0000650 Wellocks | K3: The Newt in Somerset | L3: Approved | M3: Chilled | N3: None | O3: None | P3: Yeast | Q3: Breakdown | R3: No | S3: Literature sources Saccharomyces cerevisiae | T3: 28 | U3: Days | AD3: Days | AE3: 0 | AF3: 0 | AG3: 100 | AH3: 2.68 | AI3: Kilograms | AJ3: Dry Goods | AK3: 100 | AL3: 457 | AM3: 108 | AN3: 15.9 | AO3: 1.6 | AP3: 0.23 | AT3: 9.8 | AU3: 0.01 | AY3: 4.4 | AZ3: 19.8 | BA3: 0.0495 | BC3: 2.02 | BD3: 0.0 | BH3: 610 | BI3: 25 | BJ3: 59 | BK3: 390 | BL3: 5.00 | BM3: 1.60 | BN3: 3.2 | BO3: 20 | BP3: N | BQ3: N | BR3: N | BS3: 0 | BT3: Tr | BW3: Tr | BX3: 0.0 | BZ3: Tr | CA3: Tr | CB3: 0.71 | CC3: 1.70 | CD3: 11.0 | CE3: 2.0 | CG3: 0.60 | CH3: Tr | CI3: 1250 | CJ3: 3.50 | CK3: 60.0 | CM3: No | DB3: United Kingdom | DC3: United Kingdom
A4: NPD-I10753 | B4: Salt Sea Fine (WOAFSEA10) | D4: 17-367 | E4: Salt | F4: No | G4: No | H4: Yes | I4: Copied from McCance and Widdowson (17-367) | J4: P0001426 | K4: The Newt in Somerset | L4: Approved | M4: Ambient | N4: None | O4: None | P4: Sea Salt | Q4: Breakdown | R4: No | S4: 2 samples, table salt Additive free sea salt | T4: 10 | U4: Years | AD4: Days | AE4: 0 | AF4: 0 | AG4: 100 | AH4: 8.93 | AI4: Bag | AJ4: Dry Goods | AK4: 100 | AL4: 0 | AM4: 0 | AN4: 0.0 | AO4: 0.0 | AP4: 0.00 | AQ4: 0.00 | AR4: 0.00 | AS4: 0.00 | AT4: 0.0 | AU4: 0.0 | AV4: 0.0 | AY4: 0.0 | AZ4: 40000.00 | BA4: 100.0000 | BB4: Tr | BC4: 0.00 | BD4: 0.0 | BE4: 0.0 | BH4: 89 | BI4: 10 | BJ4: 76 | BK4: 1 | BL4: 0.30 | BM4: 0.08 | BN4: 0.1 | BO4: 59900 | BP4: Tr | BQ4: N | BR4: 0.044 | BS4: 0 | BT4: 0 | BW4: 0 | BX4: 0.0 | BZ4: 0.00 | CA4: 0 | CB4: 0.00 | CC4: 0.00 | CD4: 0.0 | CE4: 0.0 | CG4: 0.00 | CH4: 0.0 | CI4: 0 | CJ4: 0.00 | CK4: 0.0 | CM4: No | DB4: Israel | DC4: Israel
A5: NPD-I10754 | B5: Whole Milk | D5: 12-596 | E5: Milk, whole, pasteurised, average | F5: No | G5: No | H5: Yes | I5: Information from product specification from Bruton Dairy | J5: P0000522 Wellocks | K5: The Newt in Somerset | L5: Approved | N5: None | O5: None | P5: Whole Milk | Q5: Breakdown | R5: No | S5: Average of summer/autumn and winter/spring standardised milk. Analytical data, 1995-1996; and industry data | T5: 11 | U5: Days | Z5: 4 | AA5: Days | AD5: Days | AE5: 0 | AF5: 0 | AG5: 100 | AH5: 2.39 | AI5: 2 Litres | AJ5: Dairy & Eggs | AK5: 100 | AL5: 282 | AM5: 68 | AN5: 3.4 | AO5: 4 | AP5: 2.6 | AT5: 4.7 | AV5: 4.7 | BA5: 0.1 | BC5: 0.53 | BD5: 0.0 | BH5: 157 | BI5: 120 | BJ5: 11 | BK5: 96 | BL5: 0.02 | BM5: Tr | BN5: 0.5 | BO5: 89 | BP5: Tr | BQ5: 1 | BR5: 0.031 | BS5: 36 | BT5: 14 | BW5: 2 | BX5: Tr | BZ5: 0.06 | CA5: 0.089544 | CB5: 0.03 | CC5: 0.23 | CD5: 0.2 | CE5: 0.6 | CG5: 0.06 | CH5: 0.9 | CI5: 8 | CJ5: 0.58 | CK5: 2.5 | CM5: No | DB5: United Kingdom | DC5: United Kingdom
A6: NPD-I10755 | B6: Dark Brown Soft Sugar, Tate & Lyle | D6: 17-060 | E6: Sugar, brown | F6: No | G6: No | H6: Yes | I6: Copied from Ritter Courivaud specification. | K6: The Newt in Somerset | L6: Approved | M6: Ambient | N6: None | O6: None | P6: Brown Sugar | Q6: Breakdown | R6: No | S6: 3 samples | T6: 730 | U6: Days | V6: 720 days from production. | AD6: Days | AE6: 0 | AF6: 0 | AG6: 100 | AH6: 6.91 | AI6: Bag | AJ6: Dry Goods | AK6: 100 | AL6: 1700 | AM6: 400 | AN6: 0.1 | AO6: 0 | AP6: 0 | AQ6: 0 | AR6: 0 | AT6: 100 | AV6: 100 | AZ6: 0.031 | BA6: 0.08 | BC6: 0.02 | BD6: 0.0 | BH6: 140 | BI6: 56 | BJ6: 17 | BK6: 4 | BL6: 1.70 | BM6: 0.06 | BN6: 0.1 | BO6: N | BP6: Tr | BQ6: Tr | BR6: Tr | BS6: 0 | BT6: 0 | BW6: 0 | BX6: 0.0 | BZ6: 0.00 | CA6: 0 | CB6: Tr | CC6: Tr | CD6: Tr | CE6: Tr | CG6: Tr | CH6: 0.0 | CI6: Tr | CJ6: Tr | CK6: Tr | CM6: No | DB6: United Kingdom | DC6: United Kingdom
A7: NPD-I10756 | B7: Water | D7: 17-377 | E7: Water, distilled | F7: No | G7: No | H7: Yes | I7: Copied from McCance and Widdowson | K7: The Newt in Somerset | L7: Approved | N7: None | O7: None | P7: Water | Q7: Breakdown | R7: No | S7: Included for recipe calculation, Wessex Water Water Supply Report uploaded Wessex water new report available on website February/March https://www.wessexwater.co.uk/your-water/water-quality | T7: 100 | U7: Years | V7: No shelf life needed | AD7: Days | AE7: 0 | AF7: 0 | AG7: 100 | AH7: 0.001 | AI7: Kilograms | AJ7: Unassigned | AK7: 100 | AL7: 0 | AM7: 0 | AN7: 0.0 | AO7: 0.0 | AP7: 0.00 | AQ7: 0.00 | AR7: 0.00 | AS7: 0.00 | AT7: 0.0 | AU7: 0.0 | AV7: 0.0 | AY7: 0.0 | AZ7: 0 | BA7: 0 | BB7: 100.0 | BC7: 0.00 | BD7: 0.0 | BE7: 0.0 | BH7: 0 | BI7: 0 | BJ7: 0 | BK7: 0 | BL7: 0.00 | BM7: 0.00 | BN7: 0.0 | BO7: 0 | BP7: 0.00 | BQ7: 0 | BR7: 0 | BS7: 0 | BT7: 0 | BW7: 0 | BX7: 0.0 | BZ7: 0.00 | CA7: 0 | CB7: 0.00 | CC7: 0.00 | CD7: 0.0 | CE7: 0.0 | CG7: 0.00 | CH7: 0.0 | CI7: 0 | CJ7: 0.00 | CK7: 0.0 | CM7: No | DB7: United Kingdom | DC7: United Kingdom
A8: NPD-I10758 | B8: WILDFARMED BREAD FLOUR (T65) | D8: 11-886 | E8: Flour, wheat, white, plain, soft | F8: No | G8: No | H8: Yes | I8: Copied from McCance and Widdowson | J8: WFWBREAD16 | K8: The Newt in Somerset | L8: Approved | M8: Ambient | N8: None | O8: None | P8: Wheat Flour | Q8: Breakdown | R8: No | S8: 14 samples, 12 products | T8: 12 | U8: Months | AD8: Days | AE8: 0 | AF8: 0 | AG8: 100 | AH8: 18.4 | AI8: Trade Paper Sack | AJ8: Dry Goods | AK8: 100 | AL8: 1501 | AM8: 352 | AN8: 9.1 | AO8: 1.4 | AP8: 0.44 | AQ8: 0.23 | AR8: 0.24 | AS8: Tr | AT8: 80.9 | AU8: 80.3 | AV8: 0.6 | AY8: 4.0 | AZ8: 2 | BA8: 0.005 | BB8: 11.6 | BC8: 1.60 | BD8: 0.0 | BE8: 0.0 | BH8: 175 | BI8: 96 | BJ8: 23 | BK8: 114 | BL8: 1.94 | BM8: 0.15 | BN8: 0.7 | BO8: 143 | BP8: 0.70 | BQ8: 3 | BR8: Tr | BS8: 0 | BT8: 0 | BW8: 0 | BX8: 0.0 | BZ8: 0.59 | CA8: 0.880516 | CB8: 0.28 | CC8: 0.05 | CD8: 1.7 | CE8: 2.0 | CG8: 0.18 | CH8: 0.0 | CI8: 16 | CJ8: 0.44 | CK8: 1.8 | CM8: No | DB8: United Kingdom | DC8: United Kingdom
A9: NPD-I10759 | B9: WILDFARMED RUSTIC FLOUR (T80) | D9: 11-887 | E9: Flour, wheat, bread/strong, white | F9: No | G9: No | H9: Yes | I9: Copied from McCance and Widdowson | J9: WFRUSTIC16 | K9: The Newt in Somerset | L9: Approved | M9: Ambient | N9: None | O9: None | P9: Wheat Flour | Q9: Breakdown | R9: No | S9: 10 samples, 9 products | T9: 12 | U9: Months | AD9: Days | AE9: 0 | AF9: 0 | AG9: 100 | AH9: 24.91 | AI9: Trade Paper Sack | AJ9: Dry Goods | AK9: 100 | AL9: 1578 | AM9: 372 | AN9: 11.6 | AO9: 0.7 | AP9: 0.15 | AT9: 77.77 | AV9: 1.13 | AY9: 4.1 | AZ9: 2.00 | BA9: 0.005 | BC9: 1.98 | BD9: 0.0 | BH9: 166 | BI9: 134 | BJ9: 26 | BK9: 128 | BL9: 1.92 | BM9: 0.15 | BN9: 0.8 | BO9: 98 | BP9: 0.67 | BQ9: 9 | BR9: Tr | BS9: 0 | BT9: 0 | BW9: 0 | BX9: 0.0 | BZ9: 0.43 | CA9: 0.641732 | CB9: 0.30 | CC9: 0.03 | CD9: 1.8 | CE9: 2.3 | CG9: 0.15 | CH9: 0.0 | CI9: 16 | CJ9: 0.30 | CK9: 1.0 | CM9: No | DB9: United Kingdom | DC9: United Kingdom
A10: NPD-I10762 | B10: Ground Almonds, Patisfrance | D10: 14-870 | E10: Almonds, flaked and ground | F10: No | G10: No | H10: Yes | I10: Copied from Ritter product specification. | K10: The Newt in Somerset | L10: Approved | M10: Ambient | N10: None | O10: None | P10: Almonds | Q10: Breakdown | R10: No | S10: 10 samples | T10: 365 | U10: Days | AD10: Days | AE10: 0 | AF10: 0 | AG10: 100 | AH10: 12.26 | AI10: Bag | AJ10: Dry Goods | AK10: 100 | AL10: 2610 | AM10: 631 | AN10: 21.4 | AO10: 52.5 | AP10: 3.95 | AT10: 8.79 | AV10: 4.63 | AY10: 9.9 | AZ10: 20.00 | BA10: 0.05 | BC10: 4.07 | BD10: 0.0 | BH10: 780 | BI10: 240 | BJ10: 270 | BK10: 550 | BL10: 3.00 | BM10: 1.00 | BN10: 3.2 | BO10: 18 | BP10: 1.70 | BQ10: 2 | BR10: 0.002 | BS10: 0 | BT10: 0 | BW10: 0 | BX10: 0.0 | BZ10: 23.96 | CA10: 35.757904 | CB10: 0.21 | CC10: 0.75 | CD10: 3.1 | CE10: 3.4 | CG10: 0.15 | CH10: 0.0 | CI10: 48 | CJ10: 0.44 | CK10: 64.0 | CM10: No | DB10: France | DC10: France
A11: NPD-I10763 | B11: Peeled Green Pistachio Nuts Afropol | D11: 14-840 | E11: Pistachio nuts, kernel only, roasted and salted | F11: No | G11: No | H11: Yes | I11: Copied from Ritter Courivaud specification. | J11: 100124 | K11: The Newt in Somerset | L11: Approved | N11: None | O11: None | P11: Pistachios | Q11: Breakdown | R11: No | S11: 10 samples | T11: 360 | U11: Days | W11: 90 | X11: Days | AD11: Days | AE11: 0 | AF11: 0 | AG11: 100 | AH11: 45.95 | AI11: Bag | AJ11: Dry Goods | AK11: 100 | AL11: 2549 | AM11: 616 | AN11: 20.6 | AO11: 51.6 | AP11: 8.6 | AT11: 11.5 | AV11: 2.8 | AY11: 11.5 | AZ11: 12.00 | BA11: 0.03 | BC11: 3.38 | BD11: 0.0 | BH11: 1040 | BI11: 110 | BJ11: 130 | BK11: 420 | BL11: 3.00 | BM11: 0.83 | BN11: 2.2 | BO11: 810 | BP11: 0.90 | BQ11: 6 | BR11: N | BS11: 0 | BT11: 130 | BW11: 0 | BX11: 0.0 | BZ11: 4.16 | CA11: 6.208384 | CB11: 0.70 | CC11: 0.23 | CD11: 1.7 | CE11: 3.9 | CG11: N | CH11: 0.0 | CI11: 58 | CJ11: N | CK11: N | CM11: No | DB11: Iran | DC11: United Kingdom
A12: NPD-I10764 | B12: Almond Ground Fine, Wellocks | D12: 14-870 | E12: Almonds, flaked and ground | F12: No | G12: No | H12: Yes | I12: Copied from Wellocks product specification. | J12: P0000035 | K12: The Newt in Somerset | L12: Approved | M12: Ambient | N12: None | O12: None | P12: Almonds | Q12: Breakdown | R12: No | S12: 10 samples Blanched Almonds, ground into a free glowing powder. | T12: 365 | U12: Days | W12: 90 | X12: Days | AD12: Days | AE12: 0 | AF12: 0 | AG12: 100 | AH12: 12.75 | AI12: Bag | AJ12: Dry Goods | AK12: 100 | AL12: 2600 | AM12: 629 | AN12: 21.1 | AO12: 55.8 | AP12: 4.4 | AT12: 6.9 | AV12: 4.2 | AY12: 7.4 | AZ12: 4 | BA12: 0.01 | BC12: 4.07 | BD12: 0.0 | BH12: 780 | BI12: 240 | BJ12: 270 | BK12: 550 | BL12: 3.00 | BM12: 1.00 | BN12: 3.2 | BO12: 18 | BP12: 1.70 | BQ12: 2 | BR12: 0.002 | BS12: 0 | BT12: 0 | BW12: 0 | BX12: 0.0 | BZ12: 23.96 | CA12: 35.757904 | CB12: 0.21 | CC12: 0.75 | CD12: 3.1 | CE12: 3.4 | CG12: 0.15 | CH12: 0.0 | CI12: 48 | CJ12: 0.44 | CK12: 64.0 | CM12: No | DB12: Italy, Spain, United States | DC12: United Kingdom
A13: NPD-I10765 | B13: Cream Double (2l) | D13: 12-334 | E13: Cream, fresh, double, including Jersey cream | F13: No | G13: No | H13: Yes | I13: Copied from McCance and Widdowson | J13: P0001145 | K13: The Newt in Somerset | L13: Approved | M13: Chilled | N13: None | O13: None | P13: Double Cream | Q13: Breakdown | R13: No | S13: Average of 22 samples of summer and winter cream | T13: 11 | U13: Days | AD13: Days | AE13: 0 | AF13: 0 | AG13: 100 | AH13: 11.83 | AI13: 2 litres | AJ13: Dairy & Eggs | AK13: 100 | AL13: 1919 | AM13: 466 | AN13: 1.5 | AO13: 48 | AP13: 30 | AT13: 1.6 | AV13: 1.6 | AZ13: 40.00 | BA13: 0.10 | BC13: 0.25 | BD13: 0.0 | BH13: 65 | BI13: 49 | BJ13: 5 | BK13: 52 | BL13: 0.06 | BM13: Tr | BN13: 0.2 | BO13: 36 | BP13: Tr | BQ13: 3 | BR13: 0.035 | BS13: 779 | BT13: 483 | BW13: 1 | BX13: 0.3 | BZ13: 1.64 | CA13: 2.447536 | CB13: 0.02 | CC13: 0.19 | CD13: Tr | CE13: 0.3 | CG13: 0.01 | CH13: 0.6 | CI13: 7 | CJ13: 0.23 | CK13: 0.9 | CM13: No | DB13: United Kingdom | DC13: United Kingdom
A14: NPD-I10778 | B14: Baking Powder (AF) | D14: 17-355 | E14: Baking powder | F14: No | G14: No | H14: Yes | I14: Copied from Wellocks product specification. | J14: P0018500 | K14: The Newt in Somerset | L14: Approved | M14: Dried | N14: None | O14: None | Q14: Merge | R14: No | S14: 6 samples of the same brand White fine silky powder. | T14: 9 | U14: Months | AD14: Days | AE14: 0 | AF14: 0 | AG14: 100 | AH14: 5.52 | AI14: Kilograms | AJ14: Dry Goods | AK14: 100 | AL14: 489 | AM14: 114.9 | AN14: 2.19 | AO14: 1.08 | AP14: 0.27 | AT14: 25.7 | AV14: 0.0 | AY14: 0.0 | AZ14: 15088.00 | BA14: 37.72 | BC14: 0.91 | BD14: 0.0 | BH14: 49 | BI14: 1130 | BJ14: 9 | BK14: 8430 | BL14: Tr | BM14: Tr | BN14: 2.8 | BO14: 29 | BP14: Tr | BQ14: Tr | BR14: Tr | BS14: 0 | BT14: 0 | BW14: 0 | BX14: 0.0 | BZ14: Tr | CA14: Tr | CB14: Tr | CC14: Tr | CD14: Tr | CE14: 1.0 | CG14: Tr | CH14: 0.0 | CI14: Tr | CJ14: Tr | CK14: Tr | CM14: No | DB14: United Kingdom | DC14: United Kingdom
A15: NPD-I10784 | B15: Nielsen Massey Vanilla Bean Paste 530ml | F15: No | G15: No | H15: Yes | J15: RBOPASTE530UK | K15: The Newt in Somerset | L15: Approved | N15: None | O15: None | P15: Vanilla Paste | Q15: Breakdown | R15: No | T15: 365 | U15: Days | W15: 365 | X15: Days | AC15: 5 | AD15: Days | AE15: 0 | AF15: 0 | AG15: 100 | AH15: 88.15 | AI15: Tub | AJ15: Dry Goods | AK15: 100 | AL15: 1214 | AM15: 290 | AN15: 0.26 | AO15: 1.01 | AP15: 0.24 | AT15: 53.03 | AV15: 50.34 | AY15: 3.3 | AZ15: 4.00 | BA15: 0.01 | CM15: No | DB15: United States | DC15: United Kingdom
A16: NPD-I10785 | B16: Self Raising Flour (SRWT25) | D16: 11-888 | E16: Flour, wheat, white, self raising | F16: No | G16: No | H16: Yes | I16: Copied from Wellocks product specification | J16: P0008312 | K16: The Newt in Somerset | L16: Approved | M16: Ambient | N16: None | O16: None | P16: Self Raising Flour | Q16: Breakdown | R16: No | S16: 12 samples, 10 samples | T16: 9 | U16: Months | AD16: Days | AE16: 0 | AF16: 0 | AG16: 100 | AH16: 24.72 | AI16: Sack | AJ16: Dry Goods | AK16: 100 | AL16: 1411 | AM16: 333 | AN16: 10 | AO16: 1.6 | AP16: 0.3 | AQ16: 0.00 | AR16: 0.00 | AT16: 69.7 | AV16: 0.6 | AY16: 3.8 | AZ16: 240.00 | BA16: 0.6 | BB16: 0.00 | BC16: 1.55 | BD16: 0.0 | BH16: 190 | BI16: 280 | BJ16: 25 | BK16: 463 | BL16: 1.74 | BM16: 0.12 | BN16: 0.8 | BO16: 108 | BP16: 0.84 | BQ16: 3 | BR16: Tr | BS16: 0 | BT16: 0 | BW16: 0 | BX16: 0.0 | BZ16: 0.63 | CA16: 0.940212 | CB16: 0.28 | CC16: 0.05 | CD16: 1.7 | CE16: 2.0 | CG16: 0.18 | CH16: 0.0 | CI16: 18 | CJ16: 0.44 | CK16: 1.8 | CM16: No | DB16: Italy, France, Germany, Spain, Belgium, Austria, Bulgaria, Croatia, Cyprus, Czech Republic, Denmark, Estonia, Finland, Greece, Hungary, Ireland, Latvia, Lithuania, Luxembourg, Malta, The Netherlands, Poland, Portugal, Romania, Slovakia, Slovenia, Sweden | DC16: United Kingdom
A17: NPD-I10789 | B17: Fresh Raspberries | D17: 14-375 | E17: Raspberries, raw | F17: No | G17: No | H17: Yes | I17: Supplier Spec | J17: P0025174 | K17: The Newt in Somerset | L17: Approved | M17: Chilled | N17: None | O17: None | P17: Fresh Raspberries | Q17: Breakdown | R17: No | S17: 11 samples, mixture of UK and imported A brilliant scarlet bramble fruit with a tender texture and intense, sweet flavor. | T17: 3 | U17: Days | AD17: Days | AE17: 0 | AF17: 0 | AG17: 100 | AH17: 2.61 | AI17: Punnet | AJ17: Fruit & Veg | AK17: 100 | AL17: 109 | AM17: 25 | AN17: 1.4 | AO17: 0.3 | AP17: 0.1 | AQ17: 0.1 | AR17: 0.1 | AS17: Tr | AT17: 4.6 | AU17: 0 | AV17: 4.6 | AY17: 2.5 | AZ17: 3 | BA17: 0.0075 | BB17: 87.7 | BC17: 0.13 | BD17: 0 | BE17: 0 | BH17: 164 | BI17: 16 | BJ17: 16 | BK17: 28 | BL17: 0.41 | BM17: 0.04 | BN17: 0.2 | BO17: 11 | BP17: 0.37 | BQ17: Tr | BR17: 0.004 | BS17: 0 | BT17: 6 | BW17: 19 | BX17: 0 | BZ17: 0.82 | CA17: 1.223768 | CB17: 0.01 | CC17: 0.01 | CD17: 0.5 | CE17: 0.2 | CG17: 0.11 | CH17: 0 | CI17: 55 | CJ17: 0.73 | CK17: 1.6 | CM17: No | DB17: Spain, Mexico, Belgium, The Netherlands, Portugal, United Kingdom, Morocco | DC17: United Kingdom
A18: NPD-I10790 | B18: Dark Chocolate Baking Sticks (Callebaut) | D18: 17-491 | E18: Chocolate, plain | F18: No | G18: No | H18: Yes | I18: Copied from Wellocks specification. | J18: P0003822 | K18: The Newt in Somerset | L18: Approved | M18: Ambient | N18: None | O18: None | P18: Dark Chocolate | Q18: Breakdown | R18: No | S18: 6 bars, 3 brands; 36-50% cocoa solids | T18: 24 | U18: Months | AD18: Days | AE18: 0 | AF18: 0 | AG18: 100 | AH18: 20.01 | AI18: Kilograms | AJ18: Dry Goods | AK18: 100 | AL18: 2078 | AM18: 497 | AN18: 5.0 | AO18: 25.6 | AP18: 15.3 | AQ18: 0.00 | AR18: 0.00 | AT18: 57.2 | AV18: 54.2 | AY18: 7.9 | AZ18: 4.00 | BA18: 0.01 | BC18: 0.80 | BD18: 0.0 | BH18: 300 | BI18: 33 | BJ18: 89 | BK18: 140 | BL18: 2.30 | BM18: 0.71 | BN18: 1.3 | BO18: 9 | BP18: 0.63 | BQ18: 4 | BR18: 0.003 | BS18: 15 | BT18: 15 | BW18: 0 | BX18: 0.0 | BZ18: 1.44 | CA18: 2.149056 | CB18: 0.04 | CC18: 0.06 | CD18: 0.4 | CE18: 0.7 | CG18: 0.03 | CH18: 0.0 | CI18: 12 | CJ18: 0.30 | CK18: 3.0 | CM18: No | DB18: Unknown | DC18: Belgium
A19: NPD-I10791 | B19: Dried Apple Pieces (Essentials) | D19: 14-016 | E19: Apples, eating, dried | F19: No | G19: No | H19: Yes | I19: Copied from Essentials specification | K19: The Newt in Somerset | L19: Approved | M19: Dried | N19: None | O19: None | P19: Dried Apple | Q19: Breakdown | R19: No | S19: 6 samples, 3 brands and calculation from 14-014 | AD19: Days | AE19: 0 | AF19: 0 | AG19: 100 | AH19: 147.6 | AI19: Bag | AJ19: Dry Goods | AK19: 100 | AL19: 1581 | AM19: 377 | AN19: 1.6 | AO19: 0.4 | AP19: 0.1 | AT19: 78 | AV19: 77 | AY19: 14.5 | AZ19: 40.00 | BA19: 0.1 | BC19: 0.32 | BH19: 540 | BI19: 16 | BJ19: 16 | BK19: 43 | BL19: 0.50 | BM19: 0.11 | BN19: 0.5 | BO19: 1 | BP19: 0.50 | BQ19: Tr | BR19: Tr | BS19: 0 | BT19: 91 | BW19: Tr | BX19: 0.0 | BZ19: 1.45 | CA19: 2.16398 | CB19: N | CC19: N | CD19: N | CE19: 0.3 | CG19: N | CH19: 0.0 | CI19: Tr | CJ19: Tr | CK19: N | CM19: No | DB19: Chile | DC19: United Kingdom
A20: NPD-I10801 | B20: Rapeseed Oil (Olleco) | D20: 17-041 | E20: Oil, rapeseed | F20: No | G20: No | H20: Yes | I20: Copied from Olleco product specification | K20: The Newt in Somerset | L20: Approved | M20: Ambient | N20: None | O20: None | P20: Rapeseed Oil | Q20: Breakdown | R20: No | S20: Mean of 100 samples Processing Aid - E900 antifoaming agent 5ppm Clear liquid oil suitable for culinary purposes. Produced from Non GM oilseed rapeseed. | T20: 18 | U20: Months | AD20: Days | AE20: 0 | AF20: 0 | AG20: 100 | AH20: 43.7 | AI20: Drum | AJ20: Dry Goods | AK20: 100 | AL20: 3700 | AM20: 900 | AN20: 0.0 | AO20: 100 | AP20: 7.5 | AQ20: 63 | AR20: 28 | AT20: 0.0 | AU20: 0.0 | AV20: 0.0 | AZ20: 20.00 | BA20: 0.05 | BC20: Tr | BD20: 0.0 | BH20: Tr | BI20: Tr | BJ20: Tr | BK20: Tr | BL20: 0.10 | BM20: 0.01 | BN20: Tr | BO20: Tr | BP20: Tr | BQ20: Tr | BR20: Tr | BS20: 0 | BT20: Tr | BW20: 0 | BX20: 0.0 | BZ20: 22.21 | CA20: 33.146204 | CB20: Tr | CC20: Tr | CD20: Tr | CE20: Tr | CG20: Tr | CH20: 0.0 | CI20: Tr | CJ20: Tr | CK20: Tr | CM20: No | DB20: France, Germany, Belgium, Australia, Russia, Ukraine, Austria, Czech Republic, Denmark, Hungary, Poland, Slovakia, United Kingdom | DC20: United Kingdom
A21: NPD-I10805 | B21: Potato Starch | D21: 13-598 | E21: Potato powder, instant, raw | F21: No | G21: No | H21: Yes | I21: Copied from Wellocks specification | J21: P0018584 | K21: The Newt in Somerset | L21: Approved | M21: Ambient | N21: None | O21: None | Q21: Breakdown | R21: No | S21: 10 samples, 9 brands Potato starch – a universal binder and thickener for many applications in the food industry | T21: 9 | U21: Months | AD21: Days | AE21: 0 | AF21: 0 | AG21: 100 | AH21: 3.98 | AI21: Tub | AJ21: Dry Goods | AK21: 100 | AL21: 1360 | AM21: 320 | AN21: 0.1 | AO21: 0.1 | AP21: 0.00 | AQ21: 0.00 | AR21: 0.00 | AT21: 80 | AV21: 0.00 | AZ21: 16.00 | BA21: 0.04 | BC21: 1.34 | BH21: 1430 | BI21: 73 | BJ21: 66 | BK21: 230 | BL21: 2.20 | BM21: 0.24 | BN21: 1.2 | BO21: 660 | BP21: 0.30 | BQ21: N | BR21: N | BS21: 0 | BT21: 15 | BW21: 130 | BX21: 0.0 | BZ21: 0.25 | CA21: 0.3731 | CB21: 0.05 | CC21: 0.19 | CD21: 6.6 | CE21: 2.0 | CG21: 0.84 | CH21: 0.0 | CI21: 13 | CJ21: N | CK21: N | CM21: No | DB21: Germany, The Netherlands, United Kingdom | DC21: United Kingdom
A22: NPD-I10813 | B22: Ground Nutmeg | D22: 13-877 | E22: Nutmeg, ground | F22: No | G22: No | H22: Yes | I22: Copied from Wellocks specification | J22: P0018642 | K22: The Newt in Somerset | L22: Approved | M22: Ambient | N22: None | O22: None | P22: Nutmeg | Q22: Breakdown | R22: No | S22: Literature sources | T22: 18 | U22: Months | W22: 9 | X22: Months | AD22: Days | AE22: 0 | AF22: 0 | AG22: 100 | AH22: 7.87 | AI22: Tub | AJ22: Dry Goods | AK22: 100 | AL22: 2196 | AM22: 525 | AN22: 5.84 | AO22: 36.31 | AP22: 26 | AQ22: 0.00 | AR22: 0.00 | AT22: 49.29 | AV22: 28 | AY22: 20.8 | AZ22: 16.00 | BA22: 0.04 | BC22: 1.10 | BD22: 0.0 | BH22: 350 | BI22: 180 | BJ22: 180 | BK22: 210 | BL22: 3.00 | BM22: 1.03 | BN22: 2.2 | BO22: N | BP22: 2.90 | BQ22: 2 | BR22: N | BS22: 0 | BT22: 60 | BW22: 3 | BX22: 0.0 | BZ22: N | CA22: N | CB22: 0.35 | CC22: 0.06 | CD22: 1.3 | CE22: N | CG22: 0.16 | CH22: 0.0 | CI22: 76 | CJ22: N | CK22: N | CM22: No | DB22: India, Indonesia | DC22: United Kingdom
A23: NPD-I10817 | B23: Spice Mixed | F23: No | G23: No | H23: Yes | I23: Copied from Wellocks product specification. | J23: P0018675 | K23: The Newt in Somerset | L23: Approved | N23: None | O23: None | P23: Mixed Spice | Q23: Breakdown | R23: No | T23: 18 | U23: Months | AD23: Days | AE23: 0 | AF23: 0 | AG23: 100 | AH23: 3.76 | AI23: Tub | AJ23: Dry Goods | AK23: 100 | AL23: 1328 | AM23: 321 | AN23: 9.6 | AO23: 12.6 | AP23: 1.4 | AT23: 22.2 | AV23: 17.7 | AY23: 40.5 | AZ23: 40.00 | BA23: 0.1 | CM23: No | DB23: United Kingdom | DC23: United Kingdom
A24: NPD-I10818 | B24: Sultanas Golden | D24: 14-263 | E24: Sultanas | F24: No | G24: No | H24: Yes | I24: Copied from Wellocks product specification | J24: P0001396 | K24: The Newt in Somerset | L24: Approved | M24: Ambient | N24: None | O24: None | P24: Sultanas | Q24: Breakdown | R24: No | S24: 10 samples, 9 brands; whole fruit Golden South African Sultanas. Appearance: Light golden to golden berries | T24: 270 | U24: Days | W24: 90 | X24: Days | AD24: Days | AE24: 0 | AF24: 0 | AG24: 100 | AH24: 6.1 | AI24: Bag | AJ24: Dry Goods | AK24: 100 | AL24: 1291 | AM24: 304 | AN24: 2.5 | AO24: 0.48 | AP24: 0.2 | AQ24: 0.00 | AR24: 0.00 | AT24: 71.3 | AV24: 71.2 | AY24: 2.3 | AZ24: 80.00 | BA24: 0.2 | BC24: 0.43 | BD24: 0.0 | BH24: 1060 | BI24: 64 | BJ24: 31 | BK24: 86 | BL24: 2.20 | BM24: 0.40 | BN24: 0.3 | BO24: 16 | BP24: 0.30 | BQ24: N | BR24: N | BS24: 0 | BT24: 12 | BW24: Tr | BX24: 0.0 | BZ24: 0.70 | CA24: 1.04468 | CB24: 0.09 | CC24: 0.05 | CD24: 0.8 | CE24: 0.2 | CG24: 0.25 | CH24: 0.0 | CI24: 27 | CJ24: 0.09 | CK24: 4.8 | CM24: No | DB24: South Africa | DC24: United Kingdom
A25: NPD-I10822 | B25: Oil Extra Pomace (5L) | D25: 17-038 | E25: Oil, olive | F25: No | G25: No | H25: Yes | I25: Copied from Wellocks specification | J25: P0003768 | K25: The Newt in Somerset | L25: Approved | M25: Ambient | N25: None | O25: None | P25: Olive Pomace Oil | Q25: Breakdown | R25: No | S25: Mean of 35 samples; including virgin and extra virgin olive oil | T25: 540 | U25: Days | AD25: Days | AE25: 0 | AF25: 0 | AG25: 100 | AH25: 38.13 | AI25: Drum | AJ25: Dry Goods | AK25: 100 | AL25: 3700 | AM25: 862 | AN25: 0.00 | AO25: 100 | AP25: 16 | AT25: 0 | AU25: 0.00 | AV25: 0.00 | AY25: 0.00 | AZ25: 0.00 | BA25: 0 | BC25: Tr | BD25: 0.0 | BH25: Tr | BI25: Tr | BJ25: Tr | BK25: Tr | BL25: 0.40 | BM25: 0.01 | BN25: Tr | BO25: Tr | BP25: Tr | BQ25: Tr | BR25: Tr | BS25: 0 | BT25: N | BW25: 0 | BX25: 0.0 | BZ25: 5.10 | CA25: 7.61124 | CB25: Tr | CC25: Tr | CD25: Tr | CE25: Tr | CG25: Tr | CH25: 0.0 | CI25: Tr | CJ25: Tr | CK25: Tr | CM25: No | DB25: Spain | DC25: United Kingdom
A26: NPD-I10854 | B26: Pectin Yellow Louis Francois | F26: No | G26: No | H26: Yes | I26: Copied from Wellocks product specification. | J26: P0014287 | K26: The Newt in Somerset | L26: Approved | M26: Ambient | N26: None | O26: None | P26: Pectin | Q26: Breakdown | R26: No | T26: 1 | U26: Years | AD26: Days | AE26: 0 | AF26: 0 | AG26: 100 | AH26: 57 | AI26: Tub | AJ26: Dry Goods | AK26: 100 | AL26: 770 | AM26: 190 | AN26: 1.5 | AO26: 0.0 | AP26: 0.0 | AT26: 21 | AV26: 10 | AY26: 49 | AZ26: 3280.00 | BA26: 8.2 | CM26: No | DB26: France | DC26: United Kingdom
A27: NPD-I10855 | B27: Sugar Demerara Silver Spoon | D27: 17-061 | E27: Sugar, Demerara | F27: No | G27: No | H27: Yes | I27: Copied from Wellocks product specification | J27: P0001537 | K27: The Newt in Somerset | L27: Approved | M27: Ambient | N27: None | O27: None | P27: Demerara Sugar | Q27: Breakdown | R27: No | S27: 5 samples | T27: 18 | U27: Months | V27: Information not available on Wellocks product specification. | AD27: Days | AE27: 0 | AF27: 0 | AG27: 100 | AH27: 7.05 | AI27: Bag | AJ27: Dry Goods | AK27: 100 | AL27: 1690 | AM27: 398 | AN27: 0.0 | AO27: 0.0 | AP27: 0.0 | AT27: 99.5 | AV27: 99.5 | AZ27: 0.00 | BA27: 0 | BC27: 0.08 | BD27: 0.0 | BH27: 48 | BI27: 29 | BJ27: 9 | BK27: 3 | BL27: 0.90 | BM27: 0.11 | BN27: 0.1 | BO27: 35 | BP27: Tr | BQ27: Tr | BR27: Tr | BS27: 0 | BT27: 0 | BW27: 0 | BX27: 0.0 | BZ27: 0.00 | CA27: 0 | CB27: Tr | CC27: Tr | CD27: Tr | CE27: Tr | CG27: Tr | CH27: 0.0 | CI27: Tr | CJ27: Tr | CK27: Tr | CM27: No | DB27: United Kingdom | DC27: United Kingdom
A28: NPD-I10859 | B28: Caster Sugar | D28: 17-063 | E28: Sugar, white | F28: No | G28: No | H28: Yes | I28: Copied from Ritter specification | J28: P0006216 | K28: The Newt in Somerset | L28: Approved | N28: None | O28: None | P28: Sugar | Q28: Breakdown | R28: No | S28: Granulated and loaf sugar | T28: 1095 | U28: Days | W28: 90 | X28: Days | AD28: Days | AE28: 0 | AF28: 0 | AG28: 100 | AH28: 34.91 | AI28: Bag | AJ28: Dry Goods | AK28: 100 | AL28: 1700 | AM28: 400 | AO28: 0.00 | AT28: 99.99 | AV28: 99.99 | BC28: Tr | BD28: 0.0 | BH28: 5 | BI28: 10 | BJ28: 2 | BK28: 1 | BL28: 0.20 | BM28: 0.12 | BN28: 0.1 | BO28: Tr | BP28: Tr | BQ28: Tr | BR28: Tr | BS28: 0 | BT28: 0 | BW28: 0 | BX28: 0.0 | BZ28: 0.00 | CA28: 0 | CB28: 0.00 | CC28: 0.00 | CD28: 0.0 | CE28: 0.0 | CG28: 0.00 | CH28: 0.0 | CI28: 0 | CJ28: 0.00 | CK28: 0.0 | CM28: No | DB28: United Kingdom | DC28: United Kingdom
A29: NPD-I10861 | B29: Unsalted Butter | D29: 17-661 | E29: Butter, unsalted | F29: No | G29: No | H29: Yes | I29: Copied from Brue Valley specification | J29: P0001133 Wellocks | K29: The Newt in Somerset | L29: Approved | M29: Chilled | N29: None | O29: None | Q29: Breakdown | R29: No | S29: Average of UK/Irish, Danish, French, New Zealand Spec due to be updated awaiting for Wellocks to confirm when live. | T29: 4 | U29: Weeks | AD29: Days | AE29: 0 | AF29: 0 | AG29: 100 | AH29: 64 | AI29: Box | AJ29: Dairy & Eggs | AK29: 100 | AL29: 3059 | AM29: 744 | AN29: 0.6 | AO29: 82.2 | AP29: 52.1 | AT29: 0.6 | AV29: 0.6 | BA29: 0 | BC29: 0.10 | BD29: 0.0 | BH29: 27 | BI29: 18 | BJ29: 2 | BK29: 23 | BL29: Tr | BM29: 0.01 | BN29: 0.1 | BO29: 18 | BP29: Tr | BQ29: Tr | BR29: 0.038 | BS29: 958 | BT29: 608 | BW29: Tr | BX29: 0.9 | BZ29: 1.85 | CA29: 2.76094 | CB29: Tr | CC29: 0.07 | CD29: Tr | CE29: 0.1 | CG29: Tr | CH29: 0.3 | CI29: Tr | CJ29: 0.05 | CK29: 0.2 | CM29: No | DB29: United Kingdom | DC29: United Kingdom
A30: NPD-I10862 | B30: Currants | D30: 14-074 | E30: Currants | F30: No | G30: No | H30: Yes | I30: Copied from Wellocks specification | J30: P0020948 | K30: The Newt in Somerset | L30: Approved | M30: Ambient | N30: None | O30: None | Q30: Breakdown | R30: No | S30: 10 samples, 9 brands | T30: 365 | U30: Days | W30: 90 | X30: Days | AD30: Days | AE30: 0 | AF30: 0 | AG30: 100 | AH30: 10.74 | AI30: Kilograms | AJ30: Dry Goods | AK30: 100 | AL30: 1139 | AM30: 267 | AO30: 0.4 | AP30: 0 | AQ30: 0.00 | AR30: 0.00 | AT30: 67.8 | AV30: 67.8 | AY30: 1.9 | AZ30: 0.00 | BA30: 0 | BC30: 0.37 | BD30: 0.0 | BH30: 720 | BI30: 93 | BJ30: 30 | BK30: 71 | BL30: 1.30 | BM30: 0.81 | BN30: 0.3 | BO30: 16 | BP30: 0.70 | BQ30: N | BR30: N | BS30: 0 | BT30: 6 | BW30: Tr | BX30: 0.0 | BZ30: N | CA30: N | CB30: 0.16 | CC30: 0.05 | CD30: 0.9 | CE30: 0.2 | CG30: 0.23 | CH30: 0.0 | CI30: 4 | CJ30: 0.07 | CK30: 4.8 | CM30: No | DB30: South Africa | DC30: United Kingdom
A31: NPD-I10863 | B31: Egg Pasteurised Yolk Free Range | D31: 12-939 | E31: Eggs, chicken, yolk, raw | F31: No | G31: No | H31: Yes | I31: Copied from Wellocks Specification | J31: P0000074 | K31: The Newt in Somerset | L31: Approved | M31: Chilled | N31: None | O31: None | P31: Egg Yolk | Q31: Breakdown | R31: No | S31: 12 samples from 3 egg distribution centres, including enriched cage, barn, free-range and organic | T31: 28 | U31: Days | W31: 21 | X31: Days | Z31: 48 | AA31: Hours | AD31: Days | AE31: 0 | AF31: 0 | AG31: 100 | AH31: 10.83 | AI31: Box | AJ31: Dairy & Eggs | AK31: 100 | AL31: 1437 | AM31: 347 | AO31: 31.3 | AP31: 8.8 | AQ31: 0.00 | AR31: 0.00 | AT31: 0 | AV31: 0 | AY31: 0 | AZ31: 52.00 | BA31: 0.13 | BC31: 2.62 | BH31: 124 | BI31: 149 | BJ31: 12 | BK31: 600 | BL31: 6.24 | BM31: 0.16 | BN31: 4.0 | BO31: 163 | BP31: 0.11 | BQ31: 59 | BR31: 0.13 | BS31: 447 | BT31: Tr | BW31: 0 | BX31: 12.8 | BZ31: 5.21 | CA31: 7.775404 | CB31: 0.20 | CC31: 0.59 | CD31: Tr | CE31: 2.8 | CG31: 0.35 | CH31: 8.2 | CI31: 122 | CJ31: 4.53 | CK31: 63.6 | CM31: No | DB31: United Kingdom | DC31: United Kingdom
A32: NPD-I10870 | B32: Cardamon Ground | F32: No | G32: No | H32: Yes | I32: Copied from Wellocks specification. | J32: P0018688 | K32: The Newt in Somerset | L32: Approved | M32: Ambient | N32: None | O32: None | P32: Cardamom | Q32: Breakdown | R32: No | T32: 9 | U32: Months | AD32: Days | AE32: 0 | AF32: 0 | AG32: 100 | AH32: 20.11 | AI32: Tub | AJ32: Dry Goods | AK32: 100 | AL32: 1343 | AM32: 321 | AN32: 10.76 | AO32: 6.70 | AP32: 0.68 | AT32: 40.47 | AY32: 28 | AZ32: 20.00 | BA32: 0.05 | CM32: No | DB32: Guatemala | DC32: United Kingdom
A33: NPD-I10887 | B33: Treacle Black | F33: No | G33: No | H33: Yes | I33: Copied from Wellocks product specification. | J33: P0000930 | K33: The Newt in Somerset | L33: Approved | N33: None | O33: None | P33: Treacle | Q33: Breakdown | R33: No | T33: 36 | U33: Months | AD33: Days | AE33: 0 | AF33: 0 | AG33: 100 | AH33: 23.76 | AI33: Bottle | AJ33: Dry Goods | AK33: 100 | AL33: 1344 | AM33: 316 | AN33: 0.6 | AO33: 0.2 | AP33: 0.01 | AT33: 78 | AV33: 67 | AZ33: 60.00 | BA33: 0.15 | CM33: No | DB33: United Kingdom | DC33: United Kingdom
A34: NPD-I10891 | B34: Cacao Barry BAKING STICKS 8cm | F34: No | G34: No | H34: Yes | I34: Supplier spec | J34: CHD-BB-308BY-357 | K34: The Newt in Somerset | L34: Approved | M34: Ambient | N34: None | O34: None | P34: Dark Chocolate | Q34: Breakdown | R34: No | T34: 730 | U34: Days | AD34: Days | AE34: 0 | AF34: 0 | AG34: 100 | AH34: 20.01 | AI34: Box | AJ34: Dry Goods | AK34: 100 | AL34: 2078 | AM34: 497 | AN34: 5 | AO34: 25.6 | AP34: 15.3 | AQ34: 8.3 | AR34: .9 | AT34: 57.2 | AU34: 2.2 | AV34: 54.5 | AY34: 7.9 | AZ34: 7.32 | BA34: 0.0183 | CM34: No | DB34: France | DC34: France
A35: NPD-I10893 | B35: Dorset Sea Salt | D35: 17-367 | E35: Salt | F35: No | G35: No | H35: Yes | I35: Copied from Dorset Sea Salt Specification. | J35: 01 / P0025113 | K35: The Newt in Somerset | L35: Approved | M35: Ambient | N35: None | O35: None | Q35: Breakdown | R35: No | S35: Specification available on Erudus | T35: 3 | U35: Years | Z35: 12 | AA35: Months | AD35: Days | AE35: 0 | AF35: 0 | AG35: 100 | AH35: 8.2 | AI35: Tub | AJ35: Dry Goods | AK35: 100 | AZ35: 39600.00 | BA35: 99 | BC35: 0.00 | BD35: 0.0 | BH35: 89 | BI35: 10 | BJ35: 76 | BK35: 1 | BL35: 0.30 | BM35: 0.08 | BN35: 0.1 | BO35: 59900 | BP35: Tr | BQ35: N | BR35: 0.044 | BS35: 0 | BT35: 0 | BW35: 0 | BX35: 0.0 | BZ35: 0.00 | CB35: 0.00 | CC35: 0.00 | CD35: 0.0 | CE35: 0.0 | CG35: 0.00 | CH35: 0.0 | CI35: 0 | CJ35: 0.00 | CK35: 0.0 | CM35: No | DB35: United Kingdom | DC35: United Kingdom
A36: NPD-I10894 | B36: Black Bee Honey 12kg Bulk | F36: No | G36: No | H36: Yes | I36: Black Bee Honey Specification. | K36: The Newt in Somerset | L36: Approved | M36: Ambient | N36: None | O36: None | P36: Black Bee Honey | Q36: Breakdown | R36: No | T36: 24 | U36: Months | AD36: Days | AE36: 0 | AF36: 0 | AG36: 100 | AH36: 40 | AI36: Tub | AJ36: Dry Goods | AK36: 100 | AL36: 1427 | AM36: 336 | AN36: 0.38 | AO36: 0.3 | AP36: 0.15 | AT36: 82.9 | AV36: 72.1 | AZ36: 2.00 | BA36: 0.005 | CM36: No | DB36: United Kingdom | DC36: United Kingdom
A37: NPD-I10895 | B37: Cornflour | F37: No | G37: No | H37: Yes | I37: Copied from Wellocks specification. | J37: P0018510 | K37: The Newt in Somerset | L37: Approved | M37: Ambient | N37: None | O37: None | Q37: Breakdown | R37: No | S37: Maize starch 100%. | T37: 12 | U37: Months | W37: 9 | X37: Months | AD37: Days | AE37: 0 | AF37: 0 | AG37: 100 | AH37: 6.18 | AI37: Bag | AJ37: Dry Goods | AK37: 100 | AL37: 1488 | AM37: 350 | AN37: 0.44 | AO37: 0.5 | AT37: 87.5 | AV37: 0.0 | AY37: 0.0 | AZ37: 72.00 | BA37: 0.18 | CM37: No | DB37: United Kingdom | DC37: United Kingdom
A38: NPD-I10896 | B38: Glucose Syrup | F38: No | G38: No | H38: Yes | I38: Copied from Wellocks product specification. | J38: P0019966 | K38: The Newt in Somerset | L38: Approved | M38: Ambient | N38: None | O38: None | P38: Glucose Syrup | Q38: Breakdown | R38: No | T38: 3 | U38: Months | AD38: Days | AE38: 0 | AF38: 0 | AG38: 100 | AH38: 11.02 | AI38: Tub | AJ38: Dry Goods | AK38: 100 | AL38: 1365 | AM38: 322 | AN38: 0 | AO38: 0 | AP38: 0 | AT38: 80 | AV38: 25 | AY38: 0 | AZ38: 32.00 | BA38: 0.08 | CM38: No | DB38: Belgium, United Kingdom | DC38: Belgium, United Kingdom
A39: NPD-I10897 | B39: Bicarbonate Soda (AF) | D39: 17-356 | E39: Bicarbonate of soda | F39: No | G39: No | H39: Yes | I39: Copied from McCance and Widdowson (17-356) | J39: P0018499 | K39: The Newt in Somerset | L39: Approved | M39: Dried | N39: E500 | O39: Raising Agent | P39: Sodium Bicarbonate | Q39: Breakdown | R39: No | S39: Powder fine grade is made from food grade E500 (ii) Sodium Bicarbonate. Flavour | T39: 12 | U39: Months | AD39: Days | AE39: 0 | AF39: 0 | AG39: 100 | AH39: 6.13 | AI39: Tub | AJ39: Dry Goods | AK39: 100 | AL39: 0 | AM39: 0 | AN39: 0.0 | AO39: 0.0 | AP39: 0.00 | AQ39: 0.00 | AR39: 0.00 | AT39: 0.0 | AU39: 0.0 | AV39: 0.0 | AZ39: 27360.00 | BA39: 68.4 | BB39: 0.0 | BC39: 0.00 | BD39: 0.0 | BE39: 0.0 | BH39: 0 | BI39: 0 | BJ39: 0 | BK39: 0 | BL39: 0.00 | BM39: 0.00 | BN39: 0.0 | BO39: 0 | BP39: 0.00 | BQ39: 0 | BR39: 0 | BS39: 0 | BT39: 0 | BW39: 0 | BX39: 0.0 | BZ39: 0.00 | CB39: 0.00 | CC39: 0.00 | CD39: 0.0 | CE39: 0.0 | CG39: 0.00 | CH39: 0.0 | CI39: 0 | CJ39: 0.00 | CK39: 0.0 | CM39: No | DB39: United Kingdom | DC39: United Kingdom
A40: NPD-I10900 | B40: Icing Sugar | F40: No | G40: No | H40: Yes | I40: Copied from Wellocks product specification. | J40: P0015396 | K40: The Newt in Somerset | L40: Approved | M40: Ambient | N40: None | O40: None | Q40: Breakdown | R40: No | T40: 36 | U40: Months | AD40: Days | AE40: 0 | AF40: 0 | AG40: 100 | AH40: 7.23 | AI40: Bag | AJ40: Dry Goods | AK40: 100 | AL40: 1687 | AM40: 399 | AN40: 0.0 | AO40: 0.0 | AP40: 0.0 | AT40: 99.2 | AV40: 99.2 | AZ40: 0.00 | BA40: 0 | CM40: No | DB40: United Kingdom | DC40: United Kingdom
...

Sheet Allergens
A1: Code | B1: Description | C1: Allergen | D1: Parts Per Million | E1: Contains | F1: May Contain
A2: NPD-I10754 | B2: =IFERROR(VLOOKUP(A2,Ingredients!A:B,2,0), "") | C2: Milk | D2: 0 | E2: Yes | F2: No
A3: NPD-I10758 | B3: =IFERROR(VLOOKUP(A3,Ingredients!A:B,2,0), "") | C3: Cereals containing gluten | D3: 0 | E3: Yes | F3: No
A4: NPD-I10758 | B4: =IFERROR(VLOOKUP(A4,Ingredients!A:B,2,0), "") | C4: Soya | D4: 0 | E4: No | F4: Yes
A5: NPD-I10759 | B5: =IFERROR(VLOOKUP(A5,Ingredients!A:B,2,0), "") | C5: Cereals containing gluten | D5: 0 | E5: Yes | F5: No
A6: NPD-I10759 | B6: =IFERROR(VLOOKUP(A6,Ingredients!A:B,2,0), "") | C6: Soya | D6: 0 | E6: No | F6: Yes
A7: NPD-I10762 | B7: =IFERROR(VLOOKUP(A7,Ingredients!A:B,2,0), "") | C7: Treenuts | D7: 0 | E7: Yes | F7: No
A8: NPD-I10763 | B8: =IFERROR(VLOOKUP(A8,Ingredients!A:B,2,0), "") | C8: Sulphites | D8: 0 | E8: No | F8: Yes
A9: NPD-I10763 | B9: =IFERROR(VLOOKUP(A9,Ingredients!A:B,2,0), "") | C9: Cereals containing gluten | D9: 0 | E9: No | F9: Yes
A10: NPD-I10763 | B10: =IFERROR(VLOOKUP(A10,Ingredients!A:B,2,0), "") | C10: Treenuts | D10: 0 | E10: Yes | F10: No
A11: NPD-I10763 | B11: =IFERROR(VLOOKUP(A11,Ingredients!A:B,2,0), "") | C11: Peanuts | D11: 0 | E11: No | F11: Yes
A12: NPD-I10763 | B12: =IFERROR(VLOOKUP(A12,Ingredients!A:B,2,0), "") | C12: Sesame | D12: 0 | E12: No | F12: Yes
A13: NPD-I10764 | B13: =IFERROR(VLOOKUP(A13,Ingredients!A:B,2,0), "") | C13: Cereals containing gluten | D13: 0 | E13: No | F13: Yes
... A127: NPD-I11610 | B127: =IFERROR(VLOOKUP(A127,Ingredients!A:B,2,0), "") | C127: Cereals containing gluten | D127: 0 | E127: No | F127: Yes

Sheet Composites
A1: Code | B1: Description | C1: Unique Key | D1: Composite Level 1 | E1: Composite Level 2 | F1: Composite Level 3 | G1: Composite Level 4 | H1: Additive | I1: Function | J1: Range Min | K1: Quantity | L1: Range Max | M1: Quantity Type | N1: Default Label Name | O1: Default Label Mode | P1: Use Raw Meat Equivalent | Q1: Comments | R1: Countries of Manufacture | S1: Countries of Origin | T1: Allergen | U1: Allergen
A2: NPD-I10758 | B2: =IFERROR(VLOOKUP(A2,Ingredients!A:B,2,0), "") | C2: 472f4472-fd1d-492a-b6bc-190f6caae807 | D2: Wheat Flour | H2: None | I2: None | J2: 0 | K2: 99 | L2: 0 | M2: Percent | O2: Breakdown | P2: No | T2: Cereals containing gluten
A3: NPD-I10758 | B3: =IFERROR(VLOOKUP(A3,Ingredients!A:B,2,0), "") | C3: 56481745-f191-40db-8724-23ab4794ed4e | D3: Calcium Carbonate | H3: None | I3: None | J3: 0 | K3: 0.5 | L3: 0 | M3: Percent | O3: Breakdown | P3: No
A4: NPD-I10758 | B4: =IFERROR(VLOOKUP(A4,Ingredients!A:B,2,0), "") | C4: f5956a1a-de9b-40f9-9c1c-6b03a5650616 | D4: Iron | H4: None | I4: None | J4: 0 | K4: 0.3 | L4: 0 | M4: Percent | O4: Breakdown | P4: No
A5: NPD-I10758 | B5: =IFERROR(VLOOKUP(A5,Ingredients!A:B,2,0), "") | C5: 3d2aca36-65a5-4c8e-a988-2ce1e1c8a2fa | D5: Niacin | H5: None | I5: None | J5: 0 | K5: 0.4 | L5: 0 | M5: Percent | O5: Breakdown | P5: No
A6: NPD-I10758 | B6: =IFERROR(VLOOKUP(A6,Ingredients!A:B,2,0), "") | C6: 980ba4bd-c064-4251-9d95-72b0ee573bc0 | D6: Thiamin | H6: None | I6: None | J6: 0 | K6: 0.01 | L6: 0 | M6: Percent | O6: Breakdown | P6: No
A7: NPD-I10758 | B7: =IFERROR(VLOOKUP(A7,Ingredients!A:B,2,0), "") | C7: 186f3383-d995-4def-83b1-7cd176fab5e4 | D7: Folic Acid | H7: None | I7: None | J7: 0 | K7: 0.2 | L7: 0 | M7: Percent | O7: Breakdown | P7: No
A8: NPD-I10759 | B8: =IFERROR(VLOOKUP(A8,Ingredients!A:B,2,0), "") | C8: 931ca2c3-70c7-44f1-9bd0-a73604a6497e | D8: Wheat Flour | H8: None | I8: None | J8: 0 | K8: 99 | L8: 0 | M8: Percent | O8: Breakdown | P8: No | T8: Cereals containing gluten
A9: NPD-I10759 | B9: =IFERROR(VLOOKUP(A9,Ingredients!A:B,2,0), "") | C9: 6325c926-ea99-4dc9-badc-c4b8ba1f50c9 | D9: Calcium Carbonate | H9: None | I9: None | J9: 0 | K9: 0.5 | L9: 0 | M9: Percent | O9: Breakdown | P9: No
A10: NPD-I10759 | B10: =IFERROR(VLOOKUP(A10,Ingredients!A:B,2,0), "") | C10: 684edd65-f4c6-4cf3-9a7f-c947b303521e | D10: Iron | H10: None | I10: None | J10: 0 | K10: 0.4 | L10: 0 | M10: Percent | O10: Breakdown | P10: No
A11: NPD-I10759 | B11: =IFERROR(VLOOKUP(A11,Ingredients!A:B,2,0), "") | C11: 02b0ad49-f06a-4b5e-904b-1448752c15c3 | D11: Niacin | H11: None | I11: None | J11: 0 | K11: 0.3 | L11: 0 | M11: Percent | O11: Breakdown | P11: No
A12: NPD-I10759 | B12: =IFERROR(VLOOKUP(A12,Ingredients!A:B,2,0), "") | C12: 4e13d91a-d59a-4bb8-8d67-c9429188126f | D12: Thiamin | H12: None | I12: None | J12: 0 | K12: 0.1 | L12: 0 | M12: Percent | O12: Breakdown | P12: No
A13: NPD-I10759 | B13: =IFERROR(VLOOKUP(A13,Ingredients!A:B,2,0), "") | C13: 2572da5b-5490-4ec7-a853-f44f319b60f2 | D13: Folic Acid | H13: None | I13: None | J13: 0 | K13: 0.2 | L13: 0 | M13: Percent | O13: Breakdown | P13: No
A14: NPD-I10778 | B14: =IFERROR(VLOOKUP(A14,Ingredients!A:B,2,0), "") | C14: 9f5555e6-86fb-44bd-8b34-58231adc5b28 | D14: Sodium Dihydrogen Diphosphate | H14: E450 | I14: Raising Agent | J14: 0 | K14: 40 | L14: 0 | M14: Percent | N14: Diphosphates | O14: Breakdown | P14: No
A15: NPD-I10778 | B15: =IFERROR(VLOOKUP(A15,Ingredients!A:B,2,0), "") | C15: 7beb0826-f050-4122-9e41-b5b5ae76b887 | D15: Sodium Bicarbonate | H15: E500 | I15: Raising Agent | J15: 0 | K15: 31 | L15: 0 | M15: Percent | O15: Breakdown | P15: No
A16: NPD-I10778 | B16: =IFERROR(VLOOKUP(A16,Ingredients!A:B,2,0), "") | C16: 58670c60-2b76-4930-a433-db655aa4acad | D16: Rice Flour | H16: None | I16: None | J16: 0 | K16: 29 | L16: 0 | M16: Percent | O16: Breakdown | P16: No
A17: NPD-I10784 | B17: =IFERROR(VLOOKUP(A17,Ingredients!A:B,2,0), "") | C17: 529f2df3-f1af-41c3-b568-c3583f3b97ce | D17: Sugar | H17: None | I17: None | J17: 0 | K17: 55 | L17: 0 | M17: Percent | O17: Breakdown | P17: No
A18: NPD-I10784 | B18: =IFERROR(VLOOKUP(A18,Ingredients!A:B,2,0), "") | C18: f0aac69c-e0e5-478d-bd65-7de5c9c88a1e | D18: Water | H18: None | I18: None | J18: 0 | K18: 39.99 | L18: 0 | M18: Percent | O18: Breakdown | P18: No
A19: NPD-I10784 | B19: =IFERROR(VLOOKUP(A19,Ingredients!A:B,2,0), "") | C19: 326671f7-9d72-4460-8108-789d1c82ca64 | D19: Vanilla Extract | H19: None | I19: None | J19: 0 | K19: 3 | L19: 0 | M19: Percent | O19: Breakdown | P19: No
A20: NPD-I10784 | B20: =IFERROR(VLOOKUP(A20,Ingredients!A:B,2,0), "") | C20: 685a44c1-76b8-4f52-a9bc-90e8292a0cb7 | D20: Vanilla Bean Seeds | H20: None | I20: None | J20: 0 | K20: 2 | L20: 0 | M20: Percent | O20: Breakdown | P20: No
A21: NPD-I10784 | B21: =IFERROR(VLOOKUP(A21,Ingredients!A:B,2,0), "") | C21: a0f04872-5b41-4da4-8938-130b2db4a2fa | D21: Gum Tragacanth | H21: None | I21: Thickener | J21: 0 | K21: 0.01 | L21: 0 | M21: Percent | O21: Breakdown | P21: No
A22: NPD-I10785 | B22: =IFERROR(VLOOKUP(A22,Ingredients!A:B,2,0), "") | C22: a92601da-a3a5-4ad3-a569-d86a4a377d90 | D22: Wheat Flour | H22: None | I22: None | J22: 0 | K22: 91 | L22: 0 | M22: Percent | O22: Breakdown | P22: No | T22: Cereals containing gluten
A23: NPD-I10785 | B23: =IFERROR(VLOOKUP(A23,Ingredients!A:B,2,0), "") | C23: 1020cc80-c789-4bee-8a0b-8a3dde8907a5 | D23: Calcium Carbonate | H23: None | I23: None | J23: 0 | K23: 2 | L23: 0 | M23: Percent | O23: Breakdown | P23: No
A24: NPD-I10785 | B24: =IFERROR(VLOOKUP(A24,Ingredients!A:B,2,0), "") | C24: c257cd5d-1ac5-4e48-8f98-4ea50bf719ae | D24: Iron | H24: None | I24: None | J24: 0 | K24: 2 | L24: 0 | M24: Percent | O24: Breakdown | P24: No
A25: NPD-I10785 | B25: =IFERROR(VLOOKUP(A25,Ingredients!A:B,2,0), "") | C25: 6baab362-d973-4586-ad5a-c9d9a5b1d5ca | D25: Niacin | H25: None | I25: None | J25: 0 | K25: 2 | L25: 0 | M25: Percent | O25: Breakdown | P25: No
A26: NPD-I10785 | B26: =IFERROR(VLOOKUP(A26,Ingredients!A:B,2,0), "") | C26: 021b1b88-881f-48d7-85a6-7026ec4965f4 | D26: Thiamin | H26: None | I26: None | J26: 0 | K26: 2 | L26: 0 | M26: Percent | O26: Breakdown | P26: No
A27: NPD-I10785 | B27: =IFERROR(VLOOKUP(A27,Ingredients!A:B,2,0), "") | C27: eba703bf-fbaa-459d-b1d5-ad3ae43c5d48 | D27: Mono-Calcium Phosphate | H27: E341 | I27: Raising Agent | J27: 0 | K27: 0.5 | L27: 0 | M27: Percent | O27: Breakdown | P27: No
A28: NPD-I10785 | B28: =IFERROR(VLOOKUP(A28,Ingredients!A:B,2,0), "") | C28: 4c4b0aee-649a-491c-a919-5f50d2210a9d | D28: Sodium Bicarbonate | H28: E500 | I28: Raising Agent | J28: 0 | K28: 0.5 | L28: 0 | M28: Percent | O28: Breakdown | P28: No
A29: NPD-I10790 | B29: =IFERROR(VLOOKUP(A29,Ingredients!A:B,2,0), "") | C29: 65240558-37f0-4205-b4f0-c4b94c4f2f2b | D29: Sugar | H29: None | I29: None | J29: 0 | K29: 54.5 | L29: 0 | M29: Percent | O29: Breakdown | P29: No
A30: NPD-I10790 | B30: =IFERROR(VLOOKUP(A30,Ingredients!A:B,2,0), "") | C30: 39531b64-2690-409b-a536-4036ede948ae | D30: Cocoa Mass | H30: None | I30: None | J30: 0 | K30: 42.5 | L30: 0 | M30: Percent | O30: Breakdown | P30: No
A31: NPD-I10790 | B31: =IFERROR(VLOOKUP(A31,Ingredients!A:B,2,0), "") | C31: 89c74291-3873-4304-8229-bbf76afaa780 | D31: Cocoa Butter | H31: None | I31: None | J31: 0 | K31: 2.5 | L31: 0 | M31: Percent | O31: Breakdown | P31: No
A32: NPD-I10790 | B32: =IFERROR(VLOOKUP(A32,Ingredients!A:B,2,0), "") | C32: 9bab3fac-80bc-431f-ad6a-5c8762fb3d7e | D32: Natural Vanilla Flavouring | H32: None | I32: None | J32: 0 | K32: 0.25 | L32: 0 | M32: Percent | O32: Breakdown | P32: No
A33: NPD-I10790 | B33: =IFERROR(VLOOKUP(A33,Ingredients!A:B,2,0), "") | C33: 0519e03b-6036-489a-b453-08900e50caf4 | D33: Soya Lecithin | H33: E322 | I33: Emulsifier | J33: 0 | K33: 0.25 | L33: 0 | M33: Percent | N33: Lecithins | O33: Breakdown | P33: No | T33: Soya
A34: NPD-I10817 | B34: =IFERROR(VLOOKUP(A34,Ingredients!A:B,2,0), "") | C34: 27849448-22a9-4dca-96f8-ced38894691c | D34: Coriander | H34: None | I34: None | J34: 0 | K34: 6 | L34: 0 | M34: Percent | O34: Breakdown | P34: No
A35: NPD-I10817 | B35: =IFERROR(VLOOKUP(A35,Ingredients!A:B,2,0), "") | C35: aa24acc5-293e-4073-a0d8-85a0efaa822d | D35: Cassia | H35: None | I35: None | J35: 0 | K35: 5 | L35: 0 | M35: Percent | O35: Breakdown | P35: No
A36: NPD-I10817 | B36: =IFERROR(VLOOKUP(A36,Ingredients!A:B,2,0), "") | C36: b6daf347-9351-470f-98c9-3c4794761d1f | D36: Ginger | H36: None | I36: None | J36: 0 | K36: 4 | L36: 0 | M36: Percent | O36: Breakdown | P36: No
A37: NPD-I10817 | B37: =IFERROR(VLOOKUP(A37,Ingredients!A:B,2,0), "") | C37: 60acfc0c-405a-4128-b84f-b20744db3d66 | D37: Fennel | H37: None | I37: None | J37: 0 | K37: 3 | L37: 0 | M37: Percent | O37: Breakdown | P37: No
A38: NPD-I10817 | B38: =IFERROR(VLOOKUP(A38,Ingredients!A:B,2,0), "") | C38: 72c6d65a-450c-4a20-bf0c-6b5f2fa0b8c3 | D38: Nutmeg | H38: None | I38: None | J38: 0 | K38: 2 | L38: 0 | M38: Percent | O38: Breakdown | P38: No
A39: NPD-I10817 | B39: =IFERROR(VLOOKUP(A39,Ingredients!A:B,2,0), "") | C39: 1d520a69-fa65-46f6-b80d-8ba091769c70 | D39: Cloves | H39: None | I39: None | J39: 0 | K39: 1 | L39: 0 | M39: Percent | O39: Breakdown | P39: No
A40: NPD-I10818 | B40: =IFERROR(VLOOKUP(A40,Ingredients!A:B,2,0), "") | C40: 11d4562c-113a-47f1-b8a6-d7fa51b42aff | D40: Sultanas | H40: None | I40: None | J40: 0 | K40: 97 | L40: 0 | M40: Percent | O40: Breakdown | P40: No
...

Sheet Units Of Measure
A1: Code | B1: Description | C1: UOM | D1: Quantity | E1: RUOM | F1: Ref Quantity | G1: Is Default
A2: NPD-I10748 | B2: =IFERROR(VLOOKUP(A2,Ingredients!A:B,2,0), "") | C2: Tub | D2: 1 | E2: Kilograms | F2: 0.5 | G2: No
A3: NPD-I10753 | B3: =IFERROR(VLOOKUP(A3,Ingredients!A:B,2,0), "") | C3: Bag | D3: 1 | E3: Kilograms | F3: 10 | G3: No
A4: NPD-I10754 | B4: =IFERROR(VLOOKUP(A4,Ingredients!A:B,2,0), "") | C4: 2 Litres | D4: 1 | E4: Kilograms | F4: 2 | G4: No
A5: NPD-I10755 | B5: =IFERROR(VLOOKUP(A5,Ingredients!A:B,2,0), "") | C5: Bag | D5: 1 | E5: Kilograms | F5: 3 | G5: No
A6: NPD-I10758 | B6: =IFERROR(VLOOKUP(A6,Ingredients!A:B,2,0), "") | C6: Trade Paper Sack | D6: 1 | E6: Kilograms | F6: 16 | G6: No
A7: NPD-I10759 | B7: =IFERROR(VLOOKUP(A7,Ingredients!A:B,2,0), "") | C7: Trade Paper Sack | D7: 1 | E7: Kilograms | F7: 16 | G7: No
A8: NPD-I10762 | B8: =IFERROR(VLOOKUP(A8,Ingredients!A:B,2,0), "") | C8: Bag | D8: 1 | E8: Kilograms | F8: 1 | G8: No
A9: NPD-I10763 | B9: =IFERROR(VLOOKUP(A9,Ingredients!A:B,2,0), "") | C9: Bag | D9: 1 | E9: Kilograms | F9: 1 | G9: No
A10: NPD-I10764 | B10: =IFERROR(VLOOKUP(A10,Ingredients!A:B,2,0), "") | C10: Bag | D10: 1 | E10: Kilograms | F10: 1 | G10: No
A11: NPD-I10765 | B11: =IFERROR(VLOOKUP(A11,Ingredients!A:B,2,0), "") | C11: 2 litres | D11: 1 | E11: Kilograms | F11: 2 | G11: No
A12: NPD-I10784 | B12: =IFERROR(VLOOKUP(A12,Ingredients!A:B,2,0), "") | C12: Tub | D12: 1 | E12: Kilograms | F12: 0.53 | G12: No
A13: NPD-I10785 | B13: =IFERROR(VLOOKUP(A13,Ingredients!A:B,2,0), "") | C13: Sack | D13: 1 | E13: Kilograms | F13: 16 | G13: No
... A95: NPD-I11783 | B95: =IFERROR(VLOOKUP(A95,Ingredients!A:B,2,0), "") | C95: Drum | D95: 1 | E95: Kilograms | F95: 20 | G95: No

Sheet Suppliers
A1: Code | B1: Description | C1: Supplier Code | D1: Supplier | E1: Supplier Address | F1: Is Primary Supplier | G1: Ext. Code | H1: Countries of Origin | I1: Countries of Manufacture
A2: NPD-I10748 | B2: =IFERROR(VLOOKUP(A2,Ingredients!A:B,2,0), "") | C2: S3 | D2: =IFERROR(VLOOKUP(C2,Reference!O:P,2,0), "") | F2: Yes
A3: NPD-I10752 | B3: =IFERROR(VLOOKUP(A3,Ingredients!A:B,2,0), "") | C3: S2 | D3: =IFERROR(VLOOKUP(C3,Reference!O:P,2,0), "") | E3: The Offices | North Leaze Farm | BA22 7BD | F3: Yes
A4: NPD-I10752 | B4: =IFERROR(VLOOKUP(A4,Ingredients!A:B,2,0), "") | C4: S3 | D4: =IFERROR(VLOOKUP(C4,Reference!O:P,2,0), "") | F4: No
A5: NPD-I10753 | B5: =IFERROR(VLOOKUP(A5,Ingredients!A:B,2,0), "") | C5: S3 | D5: =IFERROR(VLOOKUP(C5,Reference!O:P,2,0), "") | F5: No
A6: NPD-I10753 | B6: =IFERROR(VLOOKUP(A6,Ingredients!A:B,2,0), "") | C6: S14 | D6: =IFERROR(VLOOKUP(C6,Reference!O:P,2,0), "") | E6: The Fine Food Company UK Ltd | 20 Bennetts Field Trading Estate | BA9 9DT | F6: No
A7: NPD-I10754 | B7: =IFERROR(VLOOKUP(A7,Ingredients!A:B,2,0), "") | C7: S5 | D7: =IFERROR(VLOOKUP(C7,Reference!O:P,2,0), "") | F7: Yes
A8: NPD-I10754 | B8: =IFERROR(VLOOKUP(A8,Ingredients!A:B,2,0), "") | C8: S3 | D8: =IFERROR(VLOOKUP(C8,Reference!O:P,2,0), "") | F8: No
A9: NPD-I10755 | B9: =IFERROR(VLOOKUP(A9,Ingredients!A:B,2,0), "") | C9: S20 | D9: =IFERROR(VLOOKUP(C9,Reference!O:P,2,0), "") | F9: Yes
A10: NPD-I10756 | B10: =IFERROR(VLOOKUP(A10,Ingredients!A:B,2,0), "") | C10: S153 | D10: =IFERROR(VLOOKUP(C10,Reference!O:P,2,0), "") | F10: Yes
A11: NPD-I10756 | B11: =IFERROR(VLOOKUP(A11,Ingredients!A:B,2,0), "") | C11: S154 | D11: =IFERROR(VLOOKUP(C11,Reference!O:P,2,0), "") | F11: No
A12: NPD-I10758 | B12: =IFERROR(VLOOKUP(A12,Ingredients!A:B,2,0), "") | C12: S31 | D12: =IFERROR(VLOOKUP(C12,Reference!O:P,2,0), "") | F12: Yes
A13: NPD-I10759 | B13: =IFERROR(VLOOKUP(A13,Ingredients!A:B,2,0), "") | C13: S31 | D13: =IFERROR(VLOOKUP(C13,Reference!O:P,2,0), "") | F13: Yes
A14: NPD-I10762 | B14: =IFERROR(VLOOKUP(A14,Ingredients!A:B,2,0), "") | C14: S20 | D14: =IFERROR(VLOOKUP(C14,Reference!O:P,2,0), "") | F14: Yes
A15: NPD-I10763 | B15: =IFERROR(VLOOKUP(A15,Ingredients!A:B,2,0), "") | C15: S20 | D15: =IFERROR(VLOOKUP(C15,Reference!O:P,2,0), "") | F15: Yes
A16: NPD-I10764 | B16: =IFERROR(VLOOKUP(A16,Ingredients!A:B,2,0), "") | C16: S3 | D16: =IFERROR(VLOOKUP(C16,Reference!O:P,2,0), "") | F16: Yes
A17: NPD-I10765 | B17: =IFERROR(VLOOKUP(A17,Ingredients!A:B,2,0), "") | C17: S3 | D17: =IFERROR(VLOOKUP(C17,Reference!O:P,2,0), "") | F17: Yes
A18: NPD-I10765 | B18: =IFERROR(VLOOKUP(A18,Ingredients!A:B,2,0), "") | C18: S5 | D18: =IFERROR(VLOOKUP(C18,Reference!O:P,2,0), "") | E18: Bruton Dairy | Unit 1 | F18: No
A19: NPD-I10778 | B19: =IFERROR(VLOOKUP(A19,Ingredients!A:B,2,0), "") | C19: S3 | D19: =IFERROR(VLOOKUP(C19,Reference!O:P,2,0), "") | F19: Yes
A20: NPD-I10784 | B20: =IFERROR(VLOOKUP(A20,Ingredients!A:B,2,0), "") | C20: S20 | D20: =IFERROR(VLOOKUP(C20,Reference!O:P,2,0), "") | F20: Yes
A21: NPD-I10785 | B21: =IFERROR(VLOOKUP(A21,Ingredients!A:B,2,0), "") | C21: S3 | D21: =IFERROR(VLOOKUP(C21,Reference!O:P,2,0), "") | F21: Yes
A22: NPD-I10789 | B22: =IFERROR(VLOOKUP(A22,Ingredients!A:B,2,0), "") | C22: S3 | D22: =IFERROR(VLOOKUP(C22,Reference!O:P,2,0), "") | F22: Yes
A23: NPD-I10790 | B23: =IFERROR(VLOOKUP(A23,Ingredients!A:B,2,0), "") | C23: S3 | D23: =IFERROR(VLOOKUP(C23,Reference!O:P,2,0), "") | F23: Yes
A24: NPD-I10791 | B24: =IFERROR(VLOOKUP(A24,Ingredients!A:B,2,0), "") | C24: S13 | D24: =IFERROR(VLOOKUP(C24,Reference!O:P,2,0), "") | F24: Yes
A25: NPD-I10801 | B25: =IFERROR(VLOOKUP(A25,Ingredients!A:B,2,0), "") | C25: S19 | D25: =IFERROR(VLOOKUP(C25,Reference!O:P,2,0), "") | F25: Yes
A26: NPD-I10805 | B26: =IFERROR(VLOOKUP(A26,Ingredients!A:B,2,0), "") | C26: S3 | D26: =IFERROR(VLOOKUP(C26,Reference!O:P,2,0), "") | F26: Yes
A27: NPD-I10813 | B27: =IFERROR(VLOOKUP(A27,Ingredients!A:B,2,0), "") | C27: S3 | D27: =IFERROR(VLOOKUP(C27,Reference!O:P,2,0), "") | F27: Yes
A28: NPD-I10817 | B28: =IFERROR(VLOOKUP(A28,Ingredients!A:B,2,0), "") | C28: S3 | D28: =IFERROR(VLOOKUP(C28,Reference!O:P,2,0), "") | F28: Yes
A29: NPD-I10818 | B29: =IFERROR(VLOOKUP(A29,Ingredients!A:B,2,0), "") | C29: S3 | D29: =IFERROR(VLOOKUP(C29,Reference!O:P,2,0), "") | F29: Yes
A30: NPD-I10822 | B30: =IFERROR(VLOOKUP(A30,Ingredients!A:B,2,0), "") | C30: S3 | D30: =IFERROR(VLOOKUP(C30,Reference!O:P,2,0), "") | F30: Yes
... A34: NPD-I10859 | B34: =IFERROR(VLOOKUP(A34,Ingredients!A:B,2,0), "") | C34: S3 | D34: =IFERROR(VLOOKUP(C34,Reference!O:P,2,0), "") | F34: No
A35: NPD-I10861 | B35: =IFERROR(VLOOKUP(A35,Ingredients!A:B,2,0), "") | C35: S14 | D35: =IFERROR(VLOOKUP(C35,Reference!O:P,2,0), "") | E35: The Fine Food Company UK Ltd | 20 Bennetts Field Trading Estate | BA9 9DT | F35: Yes
A36: NPD-I10861 | B36: =IFERROR(VLOOKUP(A36,Ingredients!A:B,2,0), "") | C36: S3 | D36: =IFERROR(VLOOKUP(C36,Reference!O:P,2,0), "") | F36: No
A37: NPD-I10862 | B37: =IFERROR(VLOOKUP(A37,Ingredients!A:B,2,0), "") | C37: S3 | D37: =IFERROR(VLOOKUP(C37,Reference!O:P,2,0), "") | F37: Yes
A38: NPD-I10863 | B38: =IFERROR(VLOOKUP(A38,Ingredients!A:B,2,0), "") | C38: S3 | D38: =IFERROR(VLOOKUP(C38,Reference!O:P,2,0), "") | F38: Yes
A39: NPD-I10870 | B39: =IFERROR(VLOOKUP(A39,Ingredients!A:B,2,0), "") | C39: S3 | D39: =IFERROR(VLOOKUP(C39,Reference!O:P,2,0), "") | F39: Yes
A40: NPD-I10887 | B40: =IFERROR(VLOOKUP(A40,Ingredients!A:B,2,0), "") | C40: S3 | D40: =IFERROR(VLOOKUP(C40,Reference!O:P,2,0), "") | F40: Yes
A41: NPD-I10891 | B41: =IFERROR(VLOOKUP(A41,Ingredients!A:B,2,0), "") | C41: S20 | D41: =IFERROR(VLOOKUP(C41,Reference!O:P,2,0), "") | F41: Yes
A42: NPD-I10893 | B42: =IFERROR(VLOOKUP(A42,Ingredients!A:B,2,0), "") | C42: S50 | D42: =IFERROR(VLOOKUP(C42,Reference!O:P,2,0), "") | F42: Yes
A43: NPD-I10893 | B43: =IFERROR(VLOOKUP(A43,Ingredients!A:B,2,0), "") | C43: S3 | D43: =IFERROR(VLOOKUP(C43,Reference!O:P,2,0), "") | E43: Richard Wellocks & Sons Ltd | 4 Pendleside, | BB9 6SH | F43: No
...

Sheet Manufacturers
A1: Code | B1: Description | C1: Supplier Code | D1: Supplier | E1: Supplier Address | F1: Manufacturer Code | G1: Manufacturer | H1: Manufacturer Address | I1: Ext. Code

Sheet Composite Suppliers
A1: Code | B1: Description | C1: Composite Level 1 | D1: Composite Level 2 | E1: Composite Level 3 | F1: Composite Level 4 | G1: Supplier Code | H1: Supplier | I1: Address | J1: Ext. Code | K1: Countries of Manufacture | L1: Countries of Origin

Sheet Ingredient Customer Overrides
A1: Code | B1: Description | C1: Customer | D1: Default Label Name | E1: Default Label Mode | F1: Default Function
A2: NPD-I10748 | B2: =IFERROR(VLOOKUP(A2,Ingredients!A:B,2,0), "") | C2: 3rd Party
A3: NPD-I10748 | B3: =IFERROR(VLOOKUP(A3,Ingredients!A:B,2,0), "") | C3: Bakery
A4: NPD-I10748 | B4: =IFERROR(VLOOKUP(A4,Ingredients!A:B,2,0), "") | C4: Butchery
A5: NPD-I10748 | B5: =IFERROR(VLOOKUP(A5,Ingredients!A:B,2,0), "") | C5: CPU & NPD
A6: NPD-I10748 | B6: =IFERROR(VLOOKUP(A6,Ingredients!A:B,2,0), "") | C6: Creamery
A7: NPD-I10748 | B7: =IFERROR(VLOOKUP(A7,Ingredients!A:B,2,0), "") | C7: Cyder
A8: NPD-I10748 | B8: =IFERROR(VLOOKUP(A8,Ingredients!A:B,2,0), "") | C8: Farm Kitchen
A9: NPD-I10748 | B9: =IFERROR(VLOOKUP(A9,Ingredients!A:B,2,0), "") | C9: Gelateria
A10: NPD-I10748 | B10: =IFERROR(VLOOKUP(A10,Ingredients!A:B,2,0), "") | C10: Productive Growing
A11: NPD-I10752 | B11: =IFERROR(VLOOKUP(A11,Ingredients!A:B,2,0), "") | C11: 3rd Party
A12: NPD-I10752 | B12: =IFERROR(VLOOKUP(A12,Ingredients!A:B,2,0), "") | C12: Bakery
A13: NPD-I10752 | B13: =IFERROR(VLOOKUP(A13,Ingredients!A:B,2,0), "") | C13: Butchery
... A928: NPD-I11783 | B928: =IFERROR(VLOOKUP(A928,Ingredients!A:B,2,0), "") | C928: Productive Growing

Sheet Composite Customer Overrides
A1: Code | B1: Description | C1: Composite Level 1 | D1: Composite Level 2 | E1: Composite Level 3 | F1: Composite Level 4 | G1: 3rd Party Default Label Name | H1: 3rd Party Default Label Mode | I1: 3rd Party Default Function | J1: Bakery Default Label Name | K1: Bakery Default Label Mode | L1: Bakery Default Function | M1: Butchery Default Label Name | N1: Butchery Default Label Mode | O1: Butchery Default Function | P1: CPU & NPD Default Label Name | Q1: CPU & NPD Default Label Mode | R1: CPU & NPD Default Function | S1: Creamery Default Label Name | T1: Creamery Default Label Mode | U1: Creamery Default Function | V1: Cyder Default Label Name | W1: Cyder Default Label Mode | X1: Cyder Default Function | Y1: Farm Kitchen Default Label Name | Z1: Farm Kitchen Default Label Mode | AA1: Farm Kitchen Default Function | AB1: Gelateria Default Label Name | AC1: Gelateria Default Label Mode | AD1: Gelateria Default Function | AE1: Productive Growing Default Label Name | AF1: Productive Growing Default Label Mode | AG1: Productive Growing Default Function
A2: NPD-I10758 | B2: =IFERROR(VLOOKUP(A2,Ingredients!A:B,2,0), "") | C2: Wheat Flour
A3: NPD-I10758 | B3: =IFERROR(VLOOKUP(A3,Ingredients!A:B,2,0), "") | C3: Calcium Carbonate
A4: NPD-I10758 | B4: =IFERROR(VLOOKUP(A4,Ingredients!A:B,2,0), "") | C4: Iron
A5: NPD-I10758 | B5: =IFERROR(VLOOKUP(A5,Ingredients!A:B,2,0), "") | C5: Niacin
