Workbook
Name Status: 'Reference'!$A$4:$A$10
Name Categories: 'Reference'!$C$4:$C$24
Name Usages: 'Reference'!$E$4:$E$6
Name Suppliers: 'Reference'!$O$4:$O$173
Name MaterialClasses: 'Reference'!$G$4:$G$11
Name TimePeriod: 'Reference'!$T$4:$T$8
Name AfterOpenTimePeriod: 'Reference'!$V$4:$V$9
Name Recyclabilities: 'Reference'!$K$4:$K$8

Sheet Packaging
A1: Code | B1: Description | C1: New Code | D1: External Code | E1: Category | F1: State | G1: Default Yield % | H1: Comments | I1: Usage | J1: Classification | K1: Extended Classification | L1: Gauge | M1: Substrate | N1: Colour | O1: Recycled Content % | P1: Discrete | Q1: Unit Weight | R1: Unit Weight Comment | S1: Min Temperature | T1: Max Temperature | U1: Width | V1: Length | W1: Height | X1: Dimensions Comment | Y1: Cost | Z1: UoM | AA1: Total Shelf Life | AB1: Total Shelf Life Period | AC1: Total Shelf Life Comment | AD1: Min. Shelf Life On Arrival | AE1: Min. Shelf Life On Arrival Period | AF1: Min. Shelf Life On Arrival Comment | AG1: Shelf Life After Opening | AH1: Shelf Life After Opening Period | AI1: Shelf Life After Opening Comment | AJ1: Lead Time | AK1: Lead Time Period | AL1: Min Order Quantity | AM1: Countries of Origin | AN1: Countries Of Manufacture | AO1: Tags | AP1: Supplier Comments
A2: NPD-P2 | B2: Printed Product Label | E2: Single Label | F2: Approved | G2: 100 | H2: Non food contact. | I2: Secondary | J2: Paper | P2: No | Y2: 0.1 | Z2: Each | AA2: 1 | AB2: Years | AK2: Days
A3: NPD-P7 | B3: Vacuum Pouch 160x300mm | D3: SC60160300 | E3: Bag | F3: Approved | G3: 100 | I3: Primary | J3: Plastic | L3: 60 | M3: PA/PE Multilayer Co-extruded barrier Blown film. | N3: Colourless | P3: No | Q3: 5 | U3: 160 | V3: 300 | Y3: 28.37 | Z3: Box | AA3: 2 | AB3: Years | AK3: Days
A4: NPD-P8 | B4: Soak Pads 75x120mm | D4: MPSL75120B | E4: Soak Pad | F4: Approved | G4: 100 | H4: SUPERLITE PADS BLACK 75X120MM 4000/BOX 3000gsm | I4: Primary | P4: No | Y4: 63.35 | Z4: Box | AK4: Days
A5: NPD-P15 | B5: PANIBOIS DUC BAKING BASKET – (175X110X60MM) | D5: PP3 | E5: Tray | F5: Approved | G5: 100 | I5: Primary | J5: Wood | M5: Wood | N5: Brown | P5: Yes | Q5: 26.9 | U5: 110 | V5: 175 | W5: 60 | Y5: 59 | Z5: Case | AA5: 2 | AB5: Years | AK5: Days | AM5: France | AN5: France
A6: NPD-P16 | B6: FILM FRONT BAGS BROWN/CLEAR- 10×10″ | D6: FFBK-10 | E6: Bag | F6: Approved | G6: 100 | I6: Primary | N6: Brown | P6: No | Y6: 17.5 | Z6: Case | AK6: Days
A7: NPD-P23 | B7: Vacuum Pouch 200x300mm | D7: CBV01001 | E7: Bag | F7: Approved | G7: 100 | H7: Spec requested 24.03 | I7: Primary | J7: Plastic | M7: PA/PE Multilayer barrier film | N7: clear | O7: 0 | P7: Yes | Q7: 5 | U7: 200 | V7: 300 | Y7: 58.68 | Z7: Box | AA7: 2 | AB7: Years | AK7: Days
A8: NPD-P24 | B8: Vacuum Pouch 300x400mm | D8: 27030040 | E8: Bag | F8: Approved | G8: 100 | I8: Primary | J8: Plastic | L8: 65 | M8: Food grade PE/PA/PE co- extrusion | N8: Colourless | P8: No | Q8: 14.43 | Y8: 102.64 | Z8: Box | AA8: 2 | AB8: Years | AK8: Days
A9: NPD-P25 | B9: Vacuum Pouch 400x500mm | D9: 27040050 | E9: Bag | F9: Approved | G9: 100 | I9: Primary | J9: Plastic | L9: 65 | M9: Food grade PE/PA/PE co- extrusion | N9: Colourless | O9: 0 | P9: Yes | Q9: 26.08 | U9: 400 | V9: 500 | Y9: 110.12 | Z9: Box | AA9: 2 | AB9: Years | AK9: Days
A10: NPD-P30 | B10: Burger Disc 4" Black Paper | D10: MP40013 | E10: Unassigned | F10: Approved | G10: 100 | I10: Primary | J10: Paper | L10: 86.4 | M10: Paper | N10: Black | O10: 100 | P10: Yes | U10: 101 | V10: 101 | Y10: 7.92 | Z10: Box | AK10: Days | AM10: United Kingdom | AN10: United Kingdom
A11: NPD-P32 | B11: Thermal Label | E11: Single Label | F11: Approved | G11: 100 | H11: Internal approval - non food contact. | I11: Secondary | J11: Paper | N11: white | P11: Yes | Q11: 1 | U11: 127 | V11: 75 | Y11: 7.86 | Z11: Box | AA11: 2 | AB11: Years | AK11: Days | AM11: United Kingdom | AN11: United Kingdom
A12: NPD-P37 | B12: 5mm Black Round Matt Masonite Board (8") | D12: 205893 | E12: Unassigned | F12: Approved | G12: 100 | H12: ISO9001:ISO14001 certification | I12: Primary | J12: Laminated Boards | N12: Black | P12: No | Y12: 1 | Z12: Each | AA12: 2 | AB12: Years | AK12: Days | AM12: China | AN12: China
A13: NPD-P45 | B13: Cooking Instructions Card | E13: Unassigned | F13: Approved | G13: 100 | P13: No | Y13: 0.1 | Z13: Each | AK13: Days
A14: NPD-P46 | B14: Stand Up Pch CLEAR 500ml | D14: SUPC02 | E14: Bag | F14: Approved | G14: 100 | H14: (98 micron laminated film with barrier properties (12 micron PET, 86 micron PE) | I14: Primary | J14: Plastic | L14: 98 | M14: Plastic | N14: Clear | P14: Yes | X14: Height 230 Width 130 Depth (Gusset) 80mm | Y14: 64.89 | Z14: Box | AA14: 12 | AB14: Months | AK14: Days
A15: NPD-P52 | B15: Black Silver Board 135 X 180 600GSM | E15: Tray | F15: Approved | G15: 100 | H15: Solid Grey Board produced from 70% recycled fibre Glue Laminated on one side to black polyester, silver polyester to reverse side | I15: Primary | J15: Laminated Boards | L15: 800 | M15: Solid Grey Board produced from 70% recycled fibre | N15: Grey | O15: 70 | P15: Yes | Q15: 20 | U15: 135 | V15: 180 | Y15: 64.07 | Z15: Pack | AK15: Days
A16: NPD-P53 | B16: Gifting Tin (Large) | E16: Box | F16: Approved | G16: 100 | H16: Awaiting SAQ and product specification from the supplier. Email sent to the supplier 17/08 | P16: No | Y16: 0 | Z16: Each | AK16: Days
A17: NPD-P55 | B17: Gelato Hospitality Outer Sleeve (2.5l) | E17: Sleeve | F17: Approved | G17: 100 | I17: Secondary | J17: Cardboard | L17: 500 | N17: White | P17: No | U17: 184 | V17: 590 | Y17: 973 | Z17: 2500's | AA17: 5 | AB17: Years | AK17: Days
A18: NPD-P56 | B18: Belly Band | E18: Sleeve | F18: Approved | G18: 100 | H18: TBC - James to speak to Creative. | P18: No | Y18: 0.147 | Z18: Each | AA18: 2 | AB18: Years | AK18: Days
A19: NPD-P64 | B19: 150 x 100 + 50 mm gusset - PEPE Matt Biltong Pouch | E19: Bag | F19: Approved | G19: 100 | I19: Primary | J19: Plastic | L19: 90-120 | M19: PE-EVOH-PE | N19: Pre-printed | O19: 0 | P19: Yes | U19: 50 | V19: 150 | W19: 150 | Y19: 0.2328 | Z19: Each | AA19: 2 | AB19: Years | AK19: Days | AM19: United Kingdom | AN19: United Kingdom
A20: NPD-P65 | B20: 50CC Loose O2O® Oxygen Absorber | E20: Sachet | F20: Approved | G20: 100 | I20: Primary | J20: Plastic | L20: 90-120 | M20: PE - EVOH - PE | N20: white | P20: No | Y20: 240 | Z20: Box | AA20: 2 | AB20: Years | AK20: Days
A21: NPD-P66 | B21: 125C Tubs - Personalised | E21: Tub Pot | F21: Approved | G21: 100 | P21: No | Y21: 73.26 | Z21: per 1000 | AK21: Days
A22: NPD-P67 | B22: 125C Lid Wooden Spoon | E22: Lid | F22: Approved | G22: 100 | P22: No | Y22: 86.58 | Z22: per 1000 | AK22: Days
A23: NPD-P70 | B23: 700/350mm 20mic CENTRE FOLD FILM 1000M | D23: S/0045 | E23: Film | F23: Approved | G23: 100 | I23: Primary | J23: Plastic | L23: 20 | M23: BOPP | O23: 0 | P23: No | Q23: 7300 | Y23: 53.81 | Z23: 1000 metre | AA23: 2 | AB23: Years | AK23: Days | AP23: FILM AND FOIL - Plain Centre Folded L Sealer Film PLAIN CENTRE FOLDED L SEALER FILM CODE: S/0045 SIZE (MM): 400/200MM (8") PACK SIZE: Roll MICRON: 20
A24: NPD-P71 | B24: DISPLAY30 Retail Display Bag | D24: DISPLAY30 | E24: Bag | F24: Approved | G24: 100 | I24: Primary | J24: Plastic | L24: 40 | M24: Polypropylene | N24: Clear | O24: 0 | P24: No | U24: 65 | V24: 120 | W24: 275 | Y24: 115.72 | Z24: case | AA24: 2 | AB24: Years | AK24: Days
A25: NPD-P73 | B25: Decorative Bow | E25: Ribbon | F25: Approved | G25: 100 | P25: No | Y25: 0.25 | Z25: Each | AK25: Days
A26: NPD-P74 | B26: 140 x 200 x 60 mm gusset - PEPE Matt Biltong Pouch | E26: Bag | F26: Approved | G26: 100 | I26: Primary | J26: Plastic | L26: 90-120 | M26: PE-EVOH-PE | N26: Pre printed | O26: 0 | P26: Yes | U26: 60 | V26: 140 | W26: 200 | Y26: 0.4427 | Z26: Each | AA26: 2 | AB26: Years | AK26: Days | AM26: United Kingdom | AN26: United Kingdom
A27: NPD-P75 | B27: 200CC Loose O2O® Oxygen Absorber | D27: C1334 | E27: Sachet | F27: Approved | G27: 100 | I27: Primary | J27: Plastic | L27: 90-120 | M27: PE - EVOH -PE | N27: White | P27: No | Y27: 183 | Z27: Box | AA27: 2 | AB27: Years | AK27: Days | AN27: China
A28: NPD-P79 | B28: 375ml Round 97mm Diameter Tamper Evident Container & Lid | E28: Tub Pot | F28: Approved | G28: 100 | I28: Primary | J28: Plastic | M28: Polypropylene | N28: colourless | O28: 100 | P28: Yes | Q28: 18 | S28: 5 | T28: 95 | U28: 95 | V28: 95 | W28: 80 | Y28: 144.68 | Z28: Box | AA28: 12 | AK28: Days | AL28: 15 | AM28: Denmark | AN28: Denmark
A29: NPD-P84 | B29: Bamboo Teppo Gushi Skewer 180MM 7" 250 Per Pack | D29: SKBAMTEPPO180 | E29: Unassigned | F29: Approved | G29: 100 | I29: Primary | J29: Wood | M29: bamboo | N29: nature | P29: No | V29: 180 | Y29: 6.3 | Z29: Pack | AA29: 10 | AB29: Years | AK29: Days
A30: NPD-P86 | B30: D13/13 SP CLEAR | D30: 101071-XX | E30: Tray | F30: Approved | G30: 100 | H30: Targeted raw material blend of 80% RPET & 20% APET, with a minimum of 30% of Post-Consumer Recyclate | I30: Primary | J30: Plastic | L30: 600 | M30: RPET/PESP | N30: Clear | O30: 30 | P30: No | Q30: 29.9 | S30: -18 | T30: 25 | U30: 239 | V30: 167 | W30: 13 | Y30: 5734.61 | Z30: Batch | AA30: 2 | AB30: Years | AK30: Days
A31: NPD-P87 | B31: D13/37 CLEAR | D31: 101018-01 | E31: Tray | F31: Approved | G31: 100 | H31: Targeted raw material blend of 80% RPET & 20% APET, with a minimum of 30% of Post-Consumer Recyclate All material is produced in an A.B.A.C structure A - Virgin PET Capping Layer B - Recycled content including post-consumer and post-industrial (pre-consumer) recyclate A - Virgin PET Capping Layer C - PE Laminate (food contact side) | I31: Primary | J31: Plastic | L31: 425 | M31: RPET/PE | N31: colourless | O31: 80 | P31: No | Q31: 20.6 | S31: -18 | T31: 35 | U31: 167 | V31: 239 | W31: 37 | Y31: 5661.33 | Z31: Batch | AK31: Days
A32: NPD-P88 | B32: D13/45 CLEAR | D32: 101019-04 | E32: Tray | F32: Approved | G32: 100 | H32: Recyclable MATERIAL STRUCTURE: All material is produced in an A.B.A.C structure A - Virgin PET Capping Layer B - Recycled content including post-consumer and post-industrial (pre-consumer) recyclate A - Virgin PET Capping Layer C - PE Laminate (food contact side) | I32: Primary | J32: Plastic | L32: 425 | M32: RPET/PE | N32: Colourless | O32: 80 | P32: No | Q32: 21.2 | S32: -18 | T32: 35 | U32: 167 | V32: 239 | W32: 45 | Y32: 5661.33 | Z32: Batch | AA32: 2 | AB32: Years | AK32: Days | AM32: Ireland | AN32: Ireland
A33: NPD-P89 | B33: 0422 DIE CUT SELF LOCKING TRAY 225X225X50 711MIC KRAFTPAK (FOOD SAFE) | D33: C75798/3 | E33: Tray | F33: Approved | G33: 100 | I33: Primary | J33: Cardboard | N33: Brown | O33: 100 | P33: No | U33: 225 | V33: 225 | W33: 50 | Y33: 0.53 | Z33: Each | AA33: 2 | AB33: Years | AK33: Days
A34: NPD-P90 | B34: 0422 DIE CUT SELF LOCKING TRAY 205X100X40 711MIC KRAFTPAK (FOOD SAFE) | D34: C75800/3 | E34: Tray | F34: Approved | G34: 100 | H34: Bespoke | I34: Primary | J34: Paper | L34: 711 MIC | N34: Brown | O34: 100 | P34: No | U34: 205 | V34: 100 | W34: 40 | Y34: 0.252 | Z34: Each | AA34: 2 | AB34: Years | AK34: Days
A35: NPD-P91 | B35: 0427 DIE CUT SELF LOCKING BOX C/W 6 CELL DOUBLE THICKNESS UNASSEMBLED DIVIDER SET (50MM HIGH) 240X160X55 711MIC KRAFTPAK (FOOD SAFE) | D35: C75802/5 | E35: Box | F35: Approved | G35: 100 | H35: BRC Supplier | I35: Primary | J35: Cardboard | L35: 150 | N35: Brown | O35: 100 | P35: No | Y35: 0.815 | Z35: Each | AA35: 2 | AB35: Years | AK35: Days
A36: NPD-P92 | B36: GREASEPROOF PAPER 200X180 40GSM | D36: Z75960 | E36: Paper | F36: Approved | G36: 100 | H36: Bespoke | I36: Primary | J36: Paper | L36: 40 gsm | N36: Brown | O36: 100 | P36: No | U36: 200 | V36: 180 | Y36: 0.0784 | Z36: Each | AA36: 2 | AB36: Years | AK36: Days
A37: NPD-P93 | B37: GREASEPROOF PAPER 220X320 40GSM | D37: Z75961 | E37: Paper | F37: Approved | G37: 100 | H37: Bespoke | I37: Primary | J37: Paper | L37: 40 gsm | N37: Brown | O37: 100 | P37: No | U37: 220 | V37: 320 | Y37: 0.0784 | Z37: Each | AA37: 2 | AB37: Years | AK37: Days
A38: NPD-P94 | B38: GREASEPROOF PAPER 230X450 40GSM | D38: Z75962 | E38: Paper | F38: Approved | G38: 100 | H38: Bespoke | I38: Primary | J38: Paper | L38: 40 gsm | N38: Brown | O38: 100 | P38: No | U38: 230 | V38: 450 | Y38: 0.132 | Z38: Each | AA38: 2 | AB38: Years | AK38: Days
A39: NPD-P96 | B39: PP7 PANIBOIS SIRE WOODEN MOULD 210X145X40MM | D39: PP7 | E39: Tray | F39: Approved | G39: 100 | H39: Bespoke Attached for reference only | I39: Primary | J39: Wood | M39: Wood (Poplar) | N39: Wooden | P39: No | Q39: 55 | U39: 210 | V39: 145 | W39: 40 | Y39: 65 | Z39: per 100 | AA39: 2 | AB39: Years | AK39: Days | AM39: France
A40: NPD-P98 | B40: Vacuum Pouch 200 X 300 90MU 1000 Per Box | D40: VI90200300 | E40: Bag | F40: Approved | G40: 100 | H40: Vacuum Pouch 90 micron | I40: Primary | J40: Plastic | L40: 90 | M40: PA/PE | N40: Colourless | O40: 0 | P40: No | Q40: 11 | T40: 85 | U40: 200 | V40: 300 | Y40: 41.22 | Z40: Box | AA40: 1 | AB40: Years | AK40: Days
...

Sheet Units Of Measure
A1: Code | B1: Description | C1: UoM | D1: Quantity | E1: Reference UoM | F1: Ref Quantity | G1: Is Default
A2: NPD-P7 | B2: =IFERROR(VLOOKUP(A2,Packaging!A:B,2,0), "") | C2: Each | D2: 1000 | E2: Box | F2: 1 | G2: No
A3: NPD-P8 | B3: =IFERROR(VLOOKUP(A3,Packaging!A:B,2,0), "") | C3: Each | D3: 4000 | E3: Box | F3: 1 | G3: No
A4: NPD-P15 | B4: =IFERROR(VLOOKUP(A4,Packaging!A:B,2,0), "") | C4: Each | D4: 100 | E4: Case | F4: 1 | G4: Yes
A5: NPD-P16 | B5: =IFERROR(VLOOKUP(A5,Packaging!A:B,2,0), "") | C5: Each | D5: 1000 | E5: Case | F5: 1 | G5: Yes
A6: NPD-P23 | B6: =IFERROR(VLOOKUP(A6,Packaging!A:B,2,0), "") | C6: Each | D6: 1000 | E6: Box | F6: 1 | G6: No
A7: NPD-P24 | B7: =IFERROR(VLOOKUP(A7,Packaging!A:B,2,0), "") | C7: Each | D7: 1000 | E7: Box | F7: 1 | G7: No
A8: NPD-P25 | B8: =IFERROR(VLOOKUP(A8,Packaging!A:B,2,0), "") | C8: Each | D8: 1000 | E8: Box | F8: 1 | G8: No
A9: NPD-P30 | B9: =IFERROR(VLOOKUP(A9,Packaging!A:B,2,0), "") | C9: Each | D9: 1000 | E9: Box | F9: 1 | G9: No
A10: NPD-P32 | B10: =IFERROR(VLOOKUP(A10,Packaging!A:B,2,0), "") | C10: Each | D10: 500 | E10: Box | F10: 1 | G10: No
A11: NPD-P46 | B11: =IFERROR(VLOOKUP(A11,Packaging!A:B,2,0), "") | C11: Each | D11: 250 | E11: Box | F11: 1 | G11: No
A12: NPD-P52 | B12: =IFERROR(VLOOKUP(A12,Packaging!A:B,2,0), "") | C12: Each | D12: 1000 | E12: Pack | F12: 1 | G12: No
A13: NPD-P55 | B13: =IFERROR(VLOOKUP(A13,Packaging!A:B,2,0), "") | C13: Each | D13: 2500 | E13: 2500's | F13: 1 | G13: No
... A63: NPD-P181 | B63: =IFERROR(VLOOKUP(A63,Packaging!A:B,2,0), "") | C63: Each | D63: 1000 | E63: 1000's @ 2500 | F63: 1 | G63: No

Sheet Suppliers
A1: Code | B1: Description | C1: Supplier Code | D1: Supplier | E1: Supplier Address | F1: Ext. Code | G1: Is Primary Supplier
A2: NPD-P2 | B2: =IFERROR(VLOOKUP(A2,Packaging!A:B,2,0), "") | C2: S95 | D2: =IFERROR(VLOOKUP(C2,Reference!O:P,2,0), "") | E2: Vale Labels | UNit G | TA21 9JF | G2: Yes
A3: NPD-P7 | B3: =IFERROR(VLOOKUP(A3,Packaging!A:B,2,0), "") | C3: S40 | D3: =IFERROR(VLOOKUP(C3,Reference!O:P,2,0), "") | G3: No
A4: NPD-P7 | B4: =IFERROR(VLOOKUP(A4,Packaging!A:B,2,0), "") | C4: S43 | D4: =IFERROR(VLOOKUP(C4,Reference!O:P,2,0), "") | E4: Alliance Wales & West | Unit M Trecenydd Business Park | CF3 4EP | G4: Yes
A5: NPD-P8 | B5: =IFERROR(VLOOKUP(A5,Packaging!A:B,2,0), "") | C5: S40 | D5: =IFERROR(VLOOKUP(C5,Reference!O:P,2,0), "") | G5: Yes
A6: NPD-P15 | B6: =IFERROR(VLOOKUP(A6,Packaging!A:B,2,0), "") | C6: S42 | D6: =IFERROR(VLOOKUP(C6,Reference!O:P,2,0), "") | G6: Yes
A7: NPD-P16 | B7: =IFERROR(VLOOKUP(A7,Packaging!A:B,2,0), "") | C7: S42 | D7: =IFERROR(VLOOKUP(C7,Reference!O:P,2,0), "") | G7: Yes
A8: NPD-P23 | B8: =IFERROR(VLOOKUP(A8,Packaging!A:B,2,0), "") | C8: S43 | D8: =IFERROR(VLOOKUP(C8,Reference!O:P,2,0), "") | G8: No
A9: NPD-P24 | B9: =IFERROR(VLOOKUP(A9,Packaging!A:B,2,0), "") | C9: S43 | D9: =IFERROR(VLOOKUP(C9,Reference!O:P,2,0), "") | G9: No
A10: NPD-P25 | B10: =IFERROR(VLOOKUP(A10,Packaging!A:B,2,0), "") | C10: S43 | D10: =IFERROR(VLOOKUP(C10,Reference!O:P,2,0), "") | G10: No
A11: NPD-P30 | B11: =IFERROR(VLOOKUP(A11,Packaging!A:B,2,0), "") | C11: S40 | D11: =IFERROR(VLOOKUP(C11,Reference!O:P,2,0), "") | G11: Yes
A12: NPD-P32 | B12: =IFERROR(VLOOKUP(A12,Packaging!A:B,2,0), "") | C12: S41 | D12: =IFERROR(VLOOKUP(C12,Reference!O:P,2,0), "") | G12: Yes
A13: NPD-P37 | B13: =IFERROR(VLOOKUP(A13,Packaging!A:B,2,0), "") | C13: S48 | D13: =IFERROR(VLOOKUP(C13,Reference!O:P,2,0), "") | G13: Yes
A14: NPD-P46 | B14: =IFERROR(VLOOKUP(A14,Packaging!A:B,2,0), "") | C14: S47 | D14: =IFERROR(VLOOKUP(C14,Reference!O:P,2,0), "") | G14: Yes
A15: NPD-P52 | B15: =IFERROR(VLOOKUP(A15,Packaging!A:B,2,0), "") | C15: S40 | D15: =IFERROR(VLOOKUP(C15,Reference!O:P,2,0), "") | G15: Yes
A16: NPD-P53 | B16: =IFERROR(VLOOKUP(A16,Packaging!A:B,2,0), "") | C16: S68 | D16: =IFERROR(VLOOKUP(C16,Reference!O:P,2,0), "") | E16: Cedar Packaging Group | Unit 3 | SO51 9DJ | G16: No
A17: NPD-P55 | B17: =IFERROR(VLOOKUP(A17,Packaging!A:B,2,0), "") | C17: S98 | D17: =IFERROR(VLOOKUP(C17,Reference!O:P,2,0), "") | E17: Newton Print Ltd | Collett Way | TQ12 4PH | G17: Yes
A18: NPD-P56 | B18: =IFERROR(VLOOKUP(A18,Packaging!A:B,2,0), "") | C18: S98 | D18: =IFERROR(VLOOKUP(C18,Reference!O:P,2,0), "") | E18: Newton Print Ltd | Collett Way | TQ12 4PH | G18: Yes
A19: NPD-P64 | B19: =IFERROR(VLOOKUP(A19,Packaging!A:B,2,0), "") | C19: S77 | D19: =IFERROR(VLOOKUP(C19,Reference!O:P,2,0), "") | G19: Yes
A20: NPD-P65 | B20: =IFERROR(VLOOKUP(A20,Packaging!A:B,2,0), "") | C20: S82 | D20: =IFERROR(VLOOKUP(C20,Reference!O:P,2,0), "") | G20: No
A21: NPD-P66 | B21: =IFERROR(VLOOKUP(A21,Packaging!A:B,2,0), "") | C21: S78 | D21: =IFERROR(VLOOKUP(C21,Reference!O:P,2,0), "") | G21: Yes
A22: NPD-P70 | B22: =IFERROR(VLOOKUP(A22,Packaging!A:B,2,0), "") | C22: S45 | D22: =IFERROR(VLOOKUP(C22,Reference!O:P,2,0), "") | G22: Yes
A23: NPD-P71 | B23: =IFERROR(VLOOKUP(A23,Packaging!A:B,2,0), "") | C23: S47 | D23: =IFERROR(VLOOKUP(C23,Reference!O:P,2,0), "") | E23: Unit 1B | Lyon Way Greenford | UB6 0AQ | G23: No
A24: NPD-P74 | B24: =IFERROR(VLOOKUP(A24,Packaging!A:B,2,0), "") | C24: S77 | D24: =IFERROR(VLOOKUP(C24,Reference!O:P,2,0), "") | G24: Yes
A25: NPD-P75 | B25: =IFERROR(VLOOKUP(A25,Packaging!A:B,2,0), "") | C25: S82 | D25: =IFERROR(VLOOKUP(C25,Reference!O:P,2,0), "") | G25: Yes
A26: NPD-P79 | B26: =IFERROR(VLOOKUP(A26,Packaging!A:B,2,0), "") | C26: S89 | D26: =IFERROR(VLOOKUP(C26,Reference!O:P,2,0), "") | G26: Yes
A27: NPD-P84 | B27: =IFERROR(VLOOKUP(A27,Packaging!A:B,2,0), "") | C27: S40 | D27: =IFERROR(VLOOKUP(C27,Reference!O:P,2,0), "") | G27: Yes
A28: NPD-P86 | B28: =IFERROR(VLOOKUP(A28,Packaging!A:B,2,0), "") | C28: S90 | D28: =IFERROR(VLOOKUP(C28,Reference!O:P,2,0), "") | G28: Yes
A29: NPD-P87 | B29: =IFERROR(VLOOKUP(A29,Packaging!A:B,2,0), "") | C29: S90 | D29: =IFERROR(VLOOKUP(C29,Reference!O:P,2,0), "") | G29: Yes
A30: NPD-P88 | B30: =IFERROR(VLOOKUP(A30,Packaging!A:B,2,0), "") | C30: S90 | D30: =IFERROR(VLOOKUP(C30,Reference!O:P,2,0), "") | G30: Yes
A31: NPD-P89 | B31: =IFERROR(VLOOKUP(A31,Packaging!A:B,2,0), "") | C31: S91 | D31: =IFERROR(VLOOKUP(C31,Reference!O:P,2,0), "") | G31: Yes
A32: NPD-P90 | B32: =IFERROR(VLOOKUP(A32,Packaging!A:B,2,0), "") | C32: S91 | D32: =IFERROR(VLOOKUP(C32,Reference!O:P,2,0), "") | G32: Yes
A33: NPD-P91 | B33: =IFERROR(VLOOKUP(A33,Packaging!A:B,2,0), "") | C33: S91 | D33: =IFERROR(VLOOKUP(C33,Reference!O:P,2,0), "") | G33: Yes
A34: NPD-P92 | B34: =IFERROR(VLOOKUP(A34,Packaging!A:B,2,0), "") | C34: S91 | D34: =IFERROR(VLOOKUP(C34,Reference!O:P,2,0), "") | G34: No
A35: NPD-P93 | B35: =IFERROR(VLOOKUP(A35,Packaging!A:B,2,0), "") | C35: S91 | D35: =IFERROR(VLOOKUP(C35,Reference!O:P,2,0), "") | G35: Yes
A36: NPD-P94 | B36: =IFERROR(VLOOKUP(A36,Packaging!A:B,2,0), "") | C36: S91 | D36: =IFERROR(VLOOKUP(C36,Reference!O:P,2,0), "") | G36: Yes
A37: NPD-P96 | B37: =IFERROR(VLOOKUP(A37,Packaging!A:B,2,0), "") | C37: S42 | D37: =IFERROR(VLOOKUP(C37,Reference!O:P,2,0), "") | E37: Ambican UK | Unit 6 Commercial Way | NW10 7FX | G37: Yes
A38: NPD-P98 | B38: =IFERROR(VLOOKUP(A38,Packaging!A:B,2,0), "") | C38: S40 | D38: =IFERROR(VLOOKUP(C38,Reference!O:P,2,0), "") | G38: Yes
A39: NPD-P99 | B39: =IFERROR(VLOOKUP(A39,Packaging!A:B,2,0), "") | C39: S89 | D39: =IFERROR(VLOOKUP(C39,Reference!O:P,2,0), "") | G39: Yes
A40: NPD-P100 | B40: =IFERROR(VLOOKUP(A40,Packaging!A:B,2,0), "") | C40: S40 | D40: =IFERROR(VLOOKUP(C40,Reference!O:P,2,0), "") | G40: Yes
...

Sheet Manufacturers
A1: Code | B1: Description | C1: Supplier Code | D1: Supplier | E1: Supplier Address | F1: Manufacturer Code | G1: Manufacturer | H1: Manufacturer Address | I1: Ext. Code
A2: NPD-P65 | B2: =IFERROR(VLOOKUP(A2,Packaging!A:B,2,0), "") | C2: S82 | D2: =IFERROR(VLOOKUP(C2,Reference!O:P,2,0), "") | F2: S87 | G2: =IFERROR(VLOOKUP(F2,Reference!O:P,2,0), "")
A3: NPD-P150 | B3: =IFERROR(VLOOKUP(A3,Packaging!A:B,2,0), "") | C3: S149 | D3: =IFERROR(VLOOKUP(C3,Reference!O:P,2,0), "") | E3: Transpack Ltd | Unit K Griffin Industrial Park, | SO40 3SH | F3: S152 | G3: =IFERROR(VLOOKUP(F3,Reference!O:P,2,0), "")

Sheet Reference
A1: Status | C1: Categories | E1: Usage | G1: Material Class | I1: Tags | K1: Recyclabilities | M1: Countries | O1: Suppliers | T1: Shelf Life Periods | V1: Shelf Life After Open Periods
A3: Description | C3: Description | E3: Description | G3: Description | I3: Description | K3: Description | M3: Description | O3: Supplier Code | P3: Description | Q3: Status | R3: Categories | T3: Description | V3: Description
A4: P74 Load - Ready to Validate | C4: Bag | E4: Primary | G4: Bio Degradable | K4: Recycle | M4: Afghanistan | O4: S165 | P4: 1701 | Q4: Approved | R4: Third Party Supplier/The Newt Branded | T4: Hours | V4: Hours
A5: New | C5: Bottle | E5: Secondary | G5: Cardboard | K5: Recycle With Bags at Large Supermarket | M5: Albania | O5: S45 | P5: Abpac | Q5: Approved | R5: Packaging Supplier | T5: Days | V5: Days
A6: Data Capture | C6: Box | E6: Tertiary | G6: Glass | K6: Don't Recycle | M6: Algeria | O6: S43 | P6: Alliance | Q6: Approved | R6: Packaging Supplier | T6: Weeks | V6: Weeks
A7: Pending Approval | C7: Case End Label | G7: Laminated Boards | K7: Recycle at Recycling Point | M7: American Samoa | O7: S155 | P7: Alpma GB Limited | Q7: Archived | R7: Packaging Supplier | T7: Months | V7: Months
A8: Approved | C8: Film | G8: Metal | K8: Recycle at Coffee Shop or Recycling Point | M8: Andorra | O8: S56 | P8: Amaretti Virginia | Q8: Approved | R8: 3rd party,3rd Party/newt branded,The Newt Branded | T8: Years | V8: Years
A9: Archived | C9: Jar (Glass) | G9: Paper | M9: Angola | O9: S42 | P9: Ambican | Q9: Approved | R9: Packaging Supplier | V9: Remainder of Life
A10: Delisted | C10: Lid | G10: Plastic | M10: Anguilla | O10: S38 | P10: Ampersand Dairy | Q10: Delisted | R10: Raw Material Supplier
C11: Netting | G11: Wood | M11: Antigua & Barbuda | O11: S57 | P11: Antonelli | Q11: Approved | R11: Raw Material Supplier
C12: Outer Case | M12: Argentina | O12: S61 | P12: Arthur David | Q12: Approved | R12: Raw Material Supplier
C13: Paper | M13: Armenia | O13: S177 | P13: Atlantic Distillery | Q13: Approved | R13: The Newt Branded
C14: Plasticoat | M14: Aruba | O14: S161 | P14: Atlas - Smurfit Westrock | Q14: Approved | R14: Packaging Supplier
C15: Ribbon | M15: Australia | O15: S46 | P15: Aubrey Allen | Q15: Archived | R15: Raw Material / Third Party Supplier
C16: Sachet | M16: Austria | O16: S173 | P16: Audrey's Chocolates | Q16: Approved | R16: 3rd Party/newt branded,Third Party Supplier/The Newt Branded
C17: Single Label | M17: Azerbaijan | O17: S36 | P17: Babylonstoren | Q17: Approved | R17: Raw Material / Third Party / The Newt Branded
C18: Sleeve | M18: Bahamas | O18: S136 | P18: Bagborough Farms | Q18: Approved | R18: Raw Material Supplier
C19: Soak Pad | M19: Bahrain | O19: S169 | P19: Bakery Bits | Q19: Approved | R19: Raw Material Supplier
C20: Tin | M20: Bangladesh | O20: S64 | P20: Beech Ridge Farm | Q20: Delisted | R20: Raw Material Supplier
C21: Topper | M21: Barbados | O21: S41 | P21: Bizerba UK | Q21: Approved | R21: Packaging Supplier
C22: Tray | M22: Belarus | O22: S7 | P22: Black Bee Honey | Q22: Approved | R22: Raw Material / Third Party Supplier
C23: Tub Pot | M23: Belgium | O23: S174 | P23: Boddington's Berries | Q23: Approved
C24: Unassigned | M24: Belize | O24: S62 | P24: Bridge Farm Quail | Q24: Delisted | R24: Raw Material Supplier
M25: Benin | O25: S39 | P25: Brue Valley | Q25: Approved | R25: Raw Material Supplier
M26: Bermuda | O26: S5 | P26: Bruton Dairies | Q26: Approved | R26: Raw Material / Third Party Supplier
M27: Bhutan | O27: S87 | P27: Canjoy New Materials Co | Q27: Approved | R27: Packaging Supplier
M28: Bolivia | O28: S9 | P28: Castlemead Poultry | Q28: Delisted | R28: Raw Material Supplier
M29: Bonaire | O29: S68 | P29: Cedar Packaging Group | Q29: Approved | R29: Packaging Supplier
M30: Bosnia & Herzegovina | O30: S52 | P30: Cheddar Ales | Q30: Delisted | R30: Raw Material / Third Party Supplier
M31: Botswana | O31: S142 | P31: Chesil Smokery | Q31: Approved | R31: 3rd Party/newt branded
M32: Brazil | O32: S113 | P32: Chew Valley | Q32: Approved | R32: 3rd Party/newt branded,Raw Material / Third Party / The Newt Branded,The Newt Branded
M33: Brunei | O33: S109 | P33: Chococo | Q33: Approved | R33: The Newt Branded,Third Party Supplier/The Newt Branded
M34: Bulgaria | O34: S99 | P34: Clarence & Bean | Q34: Approved | R34: 3rd party,The Newt Branded
M35: Burkina Faso | O35: S145 | P35: Classic Fine Foods | Q35: Approved | R35: 3rd party,Raw Material Supplier
M36: Burundi | O36: S106 | P36: CNS | Q36: Archived | R36: Raw Material Supplier,The Newt Branded
... M41: Cayman Islands | O41: S10 | P41: Creedy Carver Ltd | Q41: Approved | R41: Raw Material Supplier
M42: Central African Republic | O42: S176 | P42: Crown National | Q42: New
M43: Chad | O43: S77 | P43: CS Labels Ltd | Q43: Approved | R43: Packaging Supplier
M44: Chile | O44: S11 | P44: Curtiss Pitts Deer Services | Q44: Approved | R44: Raw Material Supplier
M45: China | O45: S150 | P45: DaklaPack | Q45: Approved | R45: Packaging Supplier
...
